Workbook

Sheet READ_ME
B2: GDP PRODUCTION MODEL
B3: Production (output) approach: GDP = Gross Value Added + Taxes less subsidies on products
B5: HOW TO USE
B6: 1. Settings — set your country, currency unit, first year and constant-price base year.
B7: 2. Commodities — register each commodity: name, sector, unit, IC ratio and the commodity board it comes from.
B8: The IC ratio is the share of gross output used up as intermediate consumption (inputs). GVA = Output x (1 - IC ratio).
B9: 3. Production — enter yearly production quantities from your commodity boards (blue cells).
B10: 4. Prices — enter yearly average prices per unit, in your currency, same unit as the quantity (blue cells).
B11: 5. Other_Sectors — enter GVA directly for industries without commodity detail (manufacturing, services, government...).
B12: 6. GDP_Summary — GDP appears automatically: nominal, real (constant prices), growth, deflator and per capita.
B13: Enter 'Taxes less subsidies on products' and 'Population' on that sheet to complete the picture.
B15: COLOUR CODE
... B30: if quantity is in tonnes, the price must be per tonne. The data shipped in this file is EXAMPLE data — replace it.

Sheet Settings
A1: SETTINGS
A3: Country / economy | B3: Example Country
A4: Base year (constant prices) | B4: 2021 | D4: Must be a year with prices filled in on the Prices sheet.
A5: First year of the model | B5: 2019 | D5: The model covers 8 consecutive years from this year.
A6: Currency unit | B6: LCU | D6: e.g. 'GHS million' — label only, used in headings.

Sheet Commodities
A1: Code | B1: Commodity | C1: Sector | D1: Unit | E1: IC ratio | F1: Source (board) | G1: Notes
A2: AGR01 | B2: Cocoa beans | C2: Agriculture & Livestock | D2: tonnes | E2: 0.3 | F2: Cocoa Board
A3: AGR02 | B3: Coffee (green) | C3: Agriculture & Livestock | D3: tonnes | E3: 0.3 | F3: Coffee Board
A4: AGR03 | B4: Rubber (dry) | C4: Agriculture & Livestock | D4: tonnes | E4: 0.32 | F4: Rubber Board
A5: AGR04 | B5: Palm oil (crude) | C5: Agriculture & Livestock | D5: tonnes | E5: 0.35 | F5: Palm Oil Board
A6: AGR05 | B6: Rice (paddy) | C6: Agriculture & Livestock | D6: tonnes | E6: 0.28 | F6: Grain Board
A7: AGR06 | B7: Maize | C7: Agriculture & Livestock | D7: tonnes | E7: 0.28 | F7: Grain Board
A8: AGR07 | B8: Cotton (seed) | C8: Agriculture & Livestock | D8: tonnes | E8: 0.3 | F8: Cotton Board
A9: FOR01 | B9: Round logs | C9: Forestry | D9: m3 | E9: 0.35 | F9: Forestry Authority
A10: FOR02 | B10: Sawn timber | C10: Forestry | D10: m3 | E10: 0.4 | F10: Forestry Authority
A11: FSH01 | B11: Fish catch (marine) | C11: Fishing | D11: tonnes | E11: 0.35 | F11: Fisheries Authority
A12: MIN01 | B12: Gold | C12: Mining & Quarrying | D12: kg | E12: 0.4 | F12: Minerals Board
A13: MIN02 | B13: Diamonds | C13: Mining & Quarrying | D13: carats | E13: 0.4 | F13: Minerals Board
A14: MIN03 | B14: Iron ore | C14: Mining & Quarrying | D14: tonnes | E14: 0.45 | F14: Minerals Board

Sheet Production
A1: Commodity | B1: Unit | C1: =Settings!$B$5 | D1: =C1+1 | E1: =D1+1 | F1: =E1+1 | G1: =F1+1 | H1: =G1+1 | I1: =H1+1 | J1: =I1+1
A2: =IF(Commodities!B2="","",Commodities!B2) | B2: =IF(Commodities!D2="","",Commodities!D2) | C2: 85000 | D2: 87550 | E2: 90176.5 | F2: 92881.8 | G2: 95668.2 | H2: 98538.3 | I2: 101494.4 | J2: 104539.3
A3: =IF(Commodities!B3="","",Commodities!B3) | B3: =IF(Commodities!D3="","",Commodities!D3) | C3: 12000 | D3: 12240 | E3: 12484.8 | F3: 12734.5 | G3: 12989.2 | H3: 13249 | I3: 13513.9 | J3: 13784.2
A4: =IF(Commodities!B4="","",Commodities!B4) | B4: =IF(Commodities!D4="","",Commodities!D4) | C4: 60000 | D4: 60600 | E4: 61206 | F4: 61818.1 | G4: 62436.2 | H4: 63060.6 | I4: 63691.2 | J4: 64328.1
A5: =IF(Commodities!B5="","",Commodities!B5) | B5: =IF(Commodities!D5="","",Commodities!D5) | C5: 140000 | D5: 145600 | E5: 151424 | F5: 157481 | G5: 163780.2 | H5: 170331.4 | I5: 177144.7 | J5: 184230.4
A6: =IF(Commodities!B6="","",Commodities!B6) | B6: =IF(Commodities!D6="","",Commodities!D6) | C6: 260000 | D6: 267800 | E6: 275834 | F6: 284109 | G6: 292632.3 | H6: 301411.3 | I6: 310453.6 | J6: 319767.2
A7: =IF(Commodities!B7="","",Commodities!B7) | B7: =IF(Commodities!D7="","",Commodities!D7) | C7: 180000 | D7: 183600 | E7: 187272 | F7: 191017.4 | G7: 194837.8 | H7: 198734.5 | I7: 202709.2 | J7: 206763.4
A8: =IF(Commodities!B8="","",Commodities!B8) | B8: =IF(Commodities!D8="","",Commodities!D8) | C8: 35000 | D8: 35350 | E8: 35703.5 | F8: 36060.5 | G8: 36421.1 | H8: 36785.4 | I8: 37153.2 | J8: 37524.7
A9: =IF(Commodities!B9="","",Commodities!B9) | B9: =IF(Commodities!D9="","",Commodities!D9) | C9: 400000 | D9: 408000 | E9: 416160 | F9: 424483.2 | G9: 432972.9 | H9: 441632.3 | I9: 450465 | J9: 459474.3
A10: =IF(Commodities!B10="","",Commodities!B10) | B10: =IF(Commodities!D10="","",Commodities!D10) | C10: 120000 | D10: 122400 | E10: 124848 | F10: 127345 | G10: 129891.9 | H10: 132489.7 | I10: 135139.5 | J10: 137842.3
A11: =IF(Commodities!B11="","",Commodities!B11) | B11: =IF(Commodities!D11="","",Commodities!D11) | C11: 48000 | D11: 48480 | E11: 48964.8 | F11: 49454.4 | G11: 49949 | H11: 50448.5 | I11: 50953 | J11: 51462.5
A12: =IF(Commodities!B12="","",Commodities!B12) | B12: =IF(Commodities!D12="","",Commodities!D12) | C12: 9500 | D12: 9975 | E12: 10473.8 | F12: 10997.4 | G12: 11547.3 | H12: 12124.7 | I12: 12730.9 | J12: 13367.5
A13: =IF(Commodities!B13="","",Commodities!B13) | B13: =IF(Commodities!D13="","",Commodities!D13) | C13: 180000 | D13: 183600 | E13: 187272 | F13: 191017.4 | G13: 194837.8 | H13: 198734.5 | I13: 202709.2 | J13: 206763.4
A14: =IF(Commodities!B14="","",Commodities!B14) | B14: =IF(Commodities!D14="","",Commodities!D14) | C14: 2400000 | D14: 2472000 | E14: 2546160 | F14: 2622544.8 | G14: 2701221.1 | H14: 2782257.8 | I14: 2865725.5 | J14: 2951697.3
A15: =IF(Commodities!B15="","",Commodities!B15) | B15: =IF(Commodities!D15="","",Commodities!D15)
A16: =IF(Commodities!B16="","",Commodities!B16) | B16: =IF(Commodities!D16="","",Commodities!D16)
A17: =IF(Commodities!B17="","",Commodities!B17) | B17: =IF(Commodities!D17="","",Commodities!D17)
A18: =IF(Commodities!B18="","",Commodities!B18) | B18: =IF(Commodities!D18="","",Commodities!D18)
A19: =IF(Commodities!B19="","",Commodities!B19) | B19: =IF(Commodities!D19="","",Commodities!D19)
A20: =IF(Commodities!B20="","",Commodities!B20) | B20: =IF(Commodities!D20="","",Commodities!D20)
A21: =IF(Commodities!B21="","",Commodities!B21) | B21: =IF(Commodities!D21="","",Commodities!D21)
A22: =IF(Commodities!B22="","",Commodities!B22) | B22: =IF(Commodities!D22="","",Commodities!D22)
A23: =IF(Commodities!B23="","",Commodities!B23) | B23: =IF(Commodities!D23="","",Commodities!D23)
A24: =IF(Commodities!B24="","",Commodities!B24) | B24: =IF(Commodities!D24="","",Commodities!D24)
A25: =IF(Commodities!B25="","",Commodities!B25) | B25: =IF(Commodities!D25="","",Commodities!D25)
A26: =IF(Commodities!B26="","",Commodities!B26) | B26: =IF(Commodities!D26="","",Commodities!D26)
... A41: =IF(Commodities!B41="","",Commodities!B41) | B41: =IF(Commodities!D41="","",Commodities!D41)

Sheet Prices
A1: Commodity | B1: Unit | C1: =Production!C$1 | D1: =Production!D$1 | E1: =Production!E$1 | F1: =Production!F$1 | G1: =Production!G$1 | H1: =Production!H$1 | I1: =Production!I$1 | J1: =Production!J$1
A2: =IF(Commodities!B2="","",Commodities!B2) | B2: =IF(Commodities!D2="","",Commodities!D2) | C2: 2100 | D2: 2226 | E2: 2359.56 | F2: 2501.13 | G2: 2651.2 | H2: 2810.27 | I2: 2978.89 | J2: 3157.62
A3: =IF(Commodities!B3="","",Commodities!B3) | B3: =IF(Commodities!D3="","",Commodities!D3) | C3: 3400 | D3: 3570 | E3: 3748.5 | F3: 3935.93 | G3: 4132.72 | H3: 4339.36 | I3: 4556.33 | J3: 4784.14
A4: =IF(Commodities!B4="","",Commodities!B4) | B4: =IF(Commodities!D4="","",Commodities!D4) | C4: 1500 | D4: 1560 | E4: 1622.4 | F4: 1687.3 | G4: 1754.79 | H4: 1824.98 | I4: 1897.98 | J4: 1973.9
A5: =IF(Commodities!B5="","",Commodities!B5) | B5: =IF(Commodities!D5="","",Commodities!D5) | C5: 800 | D5: 840 | E5: 882 | F5: 926.1 | G5: 972.41 | H5: 1021.03 | I5: 1072.08 | J5: 1125.68
A6: =IF(Commodities!B6="","",Commodities!B6) | B6: =IF(Commodities!D6="","",Commodities!D6) | C6: 450 | D6: 468 | E6: 486.72 | F6: 506.19 | G6: 526.44 | H6: 547.49 | I6: 569.39 | J6: 592.17
A7: =IF(Commodities!B7="","",Commodities!B7) | B7: =IF(Commodities!D7="","",Commodities!D7) | C7: 320 | D7: 332.8 | E7: 346.11 | F7: 359.96 | G7: 374.35 | H7: 389.33 | I7: 404.9 | J7: 421.1
A8: =IF(Commodities!B8="","",Commodities!B8) | B8: =IF(Commodities!D8="","",Commodities!D8) | C8: 900 | D8: 945 | E8: 992.25 | F8: 1041.86 | G8: 1093.96 | H8: 1148.65 | I8: 1206.09 | J8: 1266.39
A9: =IF(Commodities!B9="","",Commodities!B9) | B9: =IF(Commodities!D9="","",Commodities!D9) | C9: 95 | D9: 97.85 | E9: 100.79 | F9: 103.81 | G9: 106.92 | H9: 110.13 | I9: 113.43 | J9: 116.84
A10: =IF(Commodities!B10="","",Commodities!B10) | B10: =IF(Commodities!D10="","",Commodities!D10) | C10: 260 | D10: 270.4 | E10: 281.22 | F10: 292.46 | G10: 304.16 | H10: 316.33 | I10: 328.98 | J10: 342.14
A11: =IF(Commodities!B11="","",Commodities!B11) | B11: =IF(Commodities!D11="","",Commodities!D11) | C11: 1900 | D11: 1995 | E11: 2094.75 | F11: 2199.49 | G11: 2309.46 | H11: 2424.93 | I11: 2546.18 | J11: 2673.49
A12: =IF(Commodities!B12="","",Commodities!B12) | B12: =IF(Commodities!D12="","",Commodities!D12) | C12: 58000 | D12: 62640 | E12: 67651.2 | F12: 73063.3 | G12: 78908.36 | H12: 85221.03 | I12: 92038.71 | J12: 99401.81
A13: =IF(Commodities!B13="","",Commodities!B13) | B13: =IF(Commodities!D13="","",Commodities!D13) | C13: 210 | D13: 222.6 | E13: 235.96 | F13: 250.11 | G13: 265.12 | H13: 281.03 | I13: 297.89 | J13: 315.76
A14: =IF(Commodities!B14="","",Commodities!B14) | B14: =IF(Commodities!D14="","",Commodities!D14) | C14: 75 | D14: 78.75 | E14: 82.69 | F14: 86.82 | G14: 91.16 | H14: 95.72 | I14: 100.51 | J14: 105.53
A15: =IF(Commodities!B15="","",Commodities!B15) | B15: =IF(Commodities!D15="","",Commodities!D15)
A16: =IF(Commodities!B16="","",Commodities!B16) | B16: =IF(Commodities!D16="","",Commodities!D16)
A17: =IF(Commodities!B17="","",Commodities!B17) | B17: =IF(Commodities!D17="","",Commodities!D17)
A18: =IF(Commodities!B18="","",Commodities!B18) | B18: =IF(Commodities!D18="","",Commodities!D18)
A19: =IF(Commodities!B19="","",Commodities!B19) | B19: =IF(Commodities!D19="","",Commodities!D19)
A20: =IF(Commodities!B20="","",Commodities!B20) | B20: =IF(Commodities!D20="","",Commodities!D20)
A21: =IF(Commodities!B21="","",Commodities!B21) | B21: =IF(Commodities!D21="","",Commodities!D21)
A22: =IF(Commodities!B22="","",Commodities!B22) | B22: =IF(Commodities!D22="","",Commodities!D22)
A23: =IF(Commodities!B23="","",Commodities!B23) | B23: =IF(Commodities!D23="","",Commodities!D23)
A24: =IF(Commodities!B24="","",Commodities!B24) | B24: =IF(Commodities!D24="","",Commodities!D24)
A25: =IF(Commodities!B25="","",Commodities!B25) | B25: =IF(Commodities!D25="","",Commodities!D25)
A26: =IF(Commodities!B26="","",Commodities!B26) | B26: =IF(Commodities!D26="","",Commodities!D26)
... A41: =IF(Commodities!B41="","",Commodities!B41) | B41: =IF(Commodities!D41="","",Commodities!D41)

Sheet Other_Sectors
A1: OTHER INDUSTRIES — GVA entered directly (no commodity detail)
A3: Nominal GVA (current prices) | C3: =Production!C$1 | D3: =Production!D$1 | E3: =Production!E$1 | F3: =Production!F$1 | G3: =Production!G$1 | H3: =Production!H$1 | I3: =Production!I$1 | J3: =Production!J$1
A4: Manufacturing
A5: Electricity & Water
A6: Construction
A7: Wholesale & Retail Trade
A8: Transport & Storage
A9: Accommodation & Food Services
A10: Information & Communication
A11: Financial & Insurance Services
A12: Real Estate
A13: Public Administration
A14: Education & Health
A15: Other Services
A18: Real GVA (constant base-year prices) | C18: =Production!C$1 | D18: =Production!D$1 | E18: =Production!E$1 | F18: =Production!F$1 | G18: =Production!G$1 | H18: =Production!H$1 | I18: =Production!I$1 | J18: =Production!J$1
A19: =A4
A20: =A5
A21: =A6
A22: =A7
A23: =A8
A24: =A9
A25: =A10
A26: =A11
A27: =A12
A28: =A13
A29: =A14
A30: =A15

Sheet GVA_Nominal
A1: Commodity | B1: Sector | C1: =Production!C$1 | D1: =Production!D$1 | E1: =Production!E$1 | F1: =Production!F$1 | G1: =Production!G$1 | H1: =Production!H$1 | I1: =Production!I$1 | J1: =Production!J$1
A2: =IF(Commodities!B2="","",Commodities!B2) | B2: =IF(Commodities!C2="","",Commodities!C2) | C2: =IF(OR($A2="",Production!C2="",Prices!C2=""),"",Production!C2*Prices!C2*(1-Commodities!$E2)) | D2: =IF(OR($A2="",Production!D2="",Prices!D2=""),"",Production!D2*Prices!D2*(1-Commodities!$E2)) | E2: =IF(OR($A2="",Production!E2="",Prices!E2=""),"",Production!E2*Prices!E2*(1-Commodities!$E2)) | F2: =IF(OR($A2="",Production!F2="",Prices!F2=""),"",Production!F2*Prices!F2*(1-Commodities!$E2)) | G2: =IF(OR($A2="",Production!G2="",Prices!G2=""),"",Production!G2*Prices!G2*(1-Commodities!$E2)) | H2: =IF(OR($A2="",Production!H2="",Prices!H2=""),"",Production!H2*Prices!H2*(1-Commodities!$E2)) | I2: =IF(OR($A2="",Production!I2="",Prices!I2=""),"",Production!I2*Prices!I2*(1-Commodities!$E2)) | J2: =IF(OR($A2="",Production!J2="",Prices!J2=""),"",Production!J2*Prices!J2*(1-Commodities!$E2))
A3: =IF(Commodities!B3="","",Commodities!B3) | B3: =IF(Commodities!C3="","",Commodities!C3) | C3: =IF(OR($A3="",Production!C3="",Prices!C3=""),"",Production!C3*Prices!C3*(1-Commodities!$E3)) | D3: =IF(OR($A3="",Production!D3="",Prices!D3=""),"",Production!D3*Prices!D3*(1-Commodities!$E3)) | E3: =IF(OR($A3="",Production!E3="",Prices!E3=""),"",Production!E3*Prices!E3*(1-Commodities!$E3)) | F3: =IF(OR($A3="",Production!F3="",Prices!F3=""),"",Production!F3*Prices!F3*(1-Commodities!$E3)) | G3: =IF(OR($A3="",Production!G3="",Prices!G3=""),"",Production!G3*Prices!G3*(1-Commodities!$E3)) | H3: =IF(OR($A3="",Production!H3="",Prices!H3=""),"",Production!H3*Prices!H3*(1-Commodities!$E3)) | I3: =IF(OR($A3="",Production!I3="",Prices!I3=""),"",Production!I3*Prices!I3*(1-Commodities!$E3)) | J3: =IF(OR($A3="",Production!J3="",Prices!J3=""),"",Production!J3*Prices!J3*(1-Commodities!$E3))
A4: =IF(Commodities!B4="","",Commodities!B4) | B4: =IF(Commodities!C4="","",Commodities!C4) | C4: =IF(OR($A4="",Production!C4="",Prices!C4=""),"",Production!C4*Prices!C4*(1-Commodities!$E4)) | D4: =IF(OR($A4="",Production!D4="",Prices!D4=""),"",Production!D4*Prices!D4*(1-Commodities!$E4)) | E4: =IF(OR($A4="",Production!E4="",Prices!E4=""),"",Production!E4*Prices!E4*(1-Commodities!$E4)) | F4: =IF(OR($A4="",Production!F4="",Prices!F4=""),"",Production!F4*Prices!F4*(1-Commodities!$E4)) | G4: =IF(OR($A4="",Production!G4="",Prices!G4=""),"",Production!G4*Prices!G4*(1-Commodities!$E4)) | H4: =IF(OR($A4="",Production!H4="",Prices!H4=""),"",Production!H4*Prices!H4*(1-Commodities!$E4)) | I4: =IF(OR($A4="",Production!I4="",Prices!I4=""),"",Production!I4*Prices!I4*(1-Commodities!$E4)) | J4: =IF(OR($A4="",Production!J4="",Prices!J4=""),"",Production!J4*Prices!J4*(1-Commodities!$E4))
A5: =IF(Commodities!B5="","",Commodities!B5) | B5: =IF(Commodities!C5="","",Commodities!C5) | C5: =IF(OR($A5="",Production!C5="",Prices!C5=""),"",Production!C5*Prices!C5*(1-Commodities!$E5)) | D5: =IF(OR($A5="",Production!D5="",Prices!D5=""),"",Production!D5*Prices!D5*(1-Commodities!$E5)) | E5: =IF(OR($A5="",Production!E5="",Prices!E5=""),"",Production!E5*Prices!E5*(1-Commodities!$E5)) | F5: =IF(OR($A5="",Production!F5="",Prices!F5=""),"",Production!F5*Prices!F5*(1-Commodities!$E5)) | G5: =IF(OR($A5="",Production!G5="",Prices!G5=""),"",Production!G5*Prices!G5*(1-Commodities!$E5)) | H5: =IF(OR($A5="",Production!H5="",Prices!H5=""),"",Production!H5*Prices!H5*(1-Commodities!$E5)) | I5: =IF(OR($A5="",Production!I5="",Prices!I5=""),"",Production!I5*Prices!I5*(1-Commodities!$E5)) | J5: =IF(OR($A5="",Production!J5="",Prices!J5=""),"",Production!J5*Prices!J5*(1-Commodities!$E5))
A6: =IF(Commodities!B6="","",Commodities!B6) | B6: =IF(Commodities!C6="","",Commodities!C6) | C6: =IF(OR($A6="",Production!C6="",Prices!C6=""),"",Production!C6*Prices!C6*(1-Commodities!$E6)) | D6: =IF(OR($A6="",Production!D6="",Prices!D6=""),"",Production!D6*Prices!D6*(1-Commodities!$E6)) | E6: =IF(OR($A6="",Production!E6="",Prices!E6=""),"",Production!E6*Prices!E6*(1-Commodities!$E6)) | F6: =IF(OR($A6="",Production!F6="",Prices!F6=""),"",Production!F6*Prices!F6*(1-Commodities!$E6)) | G6: =IF(OR($A6="",Production!G6="",Prices!G6=""),"",Production!G6*Prices!G6*(1-Commodities!$E6)) | H6: =IF(OR($A6="",Production!H6="",Prices!H6=""),"",Production!H6*Prices!H6*(1-Commodities!$E6)) | I6: =IF(OR($A6="",Production!I6="",Prices!I6=""),"",Production!I6*Prices!I6*(1-Commodities!$E6)) | J6: =IF(OR($A6="",Production!J6="",Prices!J6=""),"",Production!J6*Prices!J6*(1-Commodities!$E6))
A7: =IF(Commodities!B7="","",Commodities!B7) | B7: =IF(Commodities!C7="","",Commodities!C7) | C7: =IF(OR($A7="",Production!C7="",Prices!C7=""),"",Production!C7*Prices!C7*(1-Commodities!$E7)) | D7: =IF(OR($A7="",Production!D7="",Prices!D7=""),"",Production!D7*Prices!D7*(1-Commodities!$E7)) | E7: =IF(OR($A7="",Production!E7="",Prices!E7=""),"",Production!E7*Prices!E7*(1-Commodities!$E7)) | F7: =IF(OR($A7="",Production!F7="",Prices!F7=""),"",Production!F7*Prices!F7*(1-Commodities!$E7)) | G7: =IF(OR($A7="",Production!G7="",Prices!G7=""),"",Production!G7*Prices!G7*(1-Commodities!$E7)) | H7: =IF(OR($A7="",Production!H7="",Prices!H7=""),"",Production!H7*Prices!H7*(1-Commodities!$E7)) | I7: =IF(OR($A7="",Production!I7="",Prices!I7=""),"",Production!I7*Prices!I7*(1-Commodities!$E7)) | J7: =IF(OR($A7="",Production!J7="",Prices!J7=""),"",Production!J7*Prices!J7*(1-Commodities!$E7))
A8: =IF(Commodities!B8="","",Commodities!B8) | B8: =IF(Commodities!C8="","",Commodities!C8) | C8: =IF(OR($A8="",Production!C8="",Prices!C8=""),"",Production!C8*Prices!C8*(1-Commodities!$E8)) | D8: =IF(OR($A8="",Production!D8="",Prices!D8=""),"",Production!D8*Prices!D8*(1-Commodities!$E8)) | E8: =IF(OR($A8="",Production!E8="",Prices!E8=""),"",Production!E8*Prices!E8*(1-Commodities!$E8)) | F8: =IF(OR($A8="",Production!F8="",Prices!F8=""),"",Production!F8*Prices!F8*(1-Commodities!$E8)) | G8: =IF(OR($A8="",Production!G8="",Prices!G8=""),"",Production!G8*Prices!G8*(1-Commodities!$E8)) | H8: =IF(OR($A8="",Production!H8="",Prices!H8=""),"",Production!H8*Prices!H8*(1-Commodities!$E8)) | I8: =IF(OR($A8="",Production!I8="",Prices!I8=""),"",Production!I8*Prices!I8*(1-Commodities!$E8)) | J8: =IF(OR($A8="",Production!J8="",Prices!J8=""),"",Production!J8*Prices!J8*(1-Commodities!$E8))
A9: =IF(Commodities!B9="","",Commodities!B9) | B9: =IF(Commodities!C9="","",Commodities!C9) | C9: =IF(OR($A9="",Production!C9="",Prices!C9=""),"",Production!C9*Prices!C9*(1-Commodities!$E9)) | D9: =IF(OR($A9="",Production!D9="",Prices!D9=""),"",Production!D9*Prices!D9*(1-Commodities!$E9)) | E9: =IF(OR($A9="",Production!E9="",Prices!E9=""),"",Production!E9*Prices!E9*(1-Commodities!$E9)) | F9: =IF(OR($A9="",Production!F9="",Prices!F9=""),"",Production!F9*Prices!F9*(1-Commodities!$E9)) | G9: =IF(OR($A9="",Production!G9="",Prices!G9=""),"",Production!G9*Prices!G9*(1-Commodities!$E9)) | H9: =IF(OR($A9="",Production!H9="",Prices!H9=""),"",Production!H9*Prices!H9*(1-Commodities!$E9)) | I9: =IF(OR($A9="",Production!I9="",Prices!I9=""),"",Production!I9*Prices!I9*(1-Commodities!$E9)) | J9: =IF(OR($A9="",Production!J9="",Prices!J9=""),"",Production!J9*Prices!J9*(1-Commodities!$E9))
A10: =IF(Commodities!B10="","",Commodities!B10) | B10: =IF(Commodities!C10="","",Commodities!C10) | C10: =IF(OR($A10="",Production!C10="",Prices!C10=""),"",Production!C10*Prices!C10*(1-Commodities!$E10)) | D10: =IF(OR($A10="",Production!D10="",Prices!D10=""),"",Production!D10*Prices!D10*(1-Commodities!$E10)) | E10: =IF(OR($A10="",Production!E10="",Prices!E10=""),"",Production!E10*Prices!E10*(1-Commodities!$E10)) | F10: =IF(OR($A10="",Production!F10="",Prices!F10=""),"",Production!F10*Prices!F10*(1-Commodities!$E10)) | G10: =IF(OR($A10="",Production!G10="",Prices!G10=""),"",Production!G10*Prices!G10*(1-Commodities!$E10)) | H10: =IF(OR($A10="",Production!H10="",Prices!H10=""),"",Production!H10*Prices!H10*(1-Commodities!$E10)) | I10: =IF(OR($A10="",Production!I10="",Prices!I10=""),"",Production!I10*Prices!I10*(1-Commodities!$E10)) | J10: =IF(OR($A10="",Production!J10="",Prices!J10=""),"",Production!J10*Prices!J10*(1-Commodities!$E10))
A11: =IF(Commodities!B11="","",Commodities!B11) | B11: =IF(Commodities!C11="","",Commodities!C11) | C11: =IF(OR($A11="",Production!C11="",Prices!C11=""),"",Production!C11*Prices!C11*(1-Commodities!$E11)) | D11: =IF(OR($A11="",Production!D11="",Prices!D11=""),"",Production!D11*Prices!D11*(1-Commodities!$E11)) | E11: =IF(OR($A11="",Production!E11="",Prices!E11=""),"",Production!E11*Prices!E11*(1-Commodities!$E11)) | F11: =IF(OR($A11="",Production!F11="",Prices!F11=""),"",Production!F11*Prices!F11*(1-Commodities!$E11)) | G11: =IF(OR($A11="",Production!G11="",Prices!G11=""),"",Production!G11*Prices!G11*(1-Commodities!$E11)) | H11: =IF(OR($A11="",Production!H11="",Prices!H11=""),"",Production!H11*Prices!H11*(1-Commodities!$E11)) | I11: =IF(OR($A11="",Production!I11="",Prices!I11=""),"",Production!I11*Prices!I11*(1-Commodities!$E11)) | J11: =IF(OR($A11="",Production!J11="",Prices!J11=""),"",Production!J11*Prices!J11*(1-Commodities!$E11))
A12: =IF(Commodities!B12="","",Commodities!B12) | B12: =IF(Commodities!C12="","",Commodities!C12) | C12: =IF(OR($A12="",Production!C12="",Prices!C12=""),"",Production!C12*Prices!C12*(1-Commodities!$E12)) | D12: =IF(OR($A12="",Production!D12="",Prices!D12=""),"",Production!D12*Prices!D12*(1-Commodities!$E12)) | E12: =IF(OR($A12="",Production!E12="",Prices!E12=""),"",Production!E12*Prices!E12*(1-Commodities!$E12)) | F12: =IF(OR($A12="",Production!F12="",Prices!F12=""),"",Production!F12*Prices!F12*(1-Commodities!$E12)) | G12: =IF(OR($A12="",Production!G12="",Prices!G12=""),"",Production!G12*Prices!G12*(1-Commodities!$E12)) | H12: =IF(OR($A12="",Production!H12="",Prices!H12=""),"",Production!H12*Prices!H12*(1-Commodities!$E12)) | I12: =IF(OR($A12="",Production!I12="",Prices!I12=""),"",Production!I12*Prices!I12*(1-Commodities!$E12)) | J12: =IF(OR($A12="",Production!J12="",Prices!J12=""),"",Production!J12*Prices!J12*(1-Commodities!$E12))
A13: =IF(Commodities!B13="","",Commodities!B13) | B13: =IF(Commodities!C13="","",Commodities!C13) | C13: =IF(OR($A13="",Production!C13="",Prices!C13=""),"",Production!C13*Prices!C13*(1-Commodities!$E13)) | D13: =IF(OR($A13="",Production!D13="",Prices!D13=""),"",Production!D13*Prices!D13*(1-Commodities!$E13)) | E13: =IF(OR($A13="",Production!E13="",Prices!E13=""),"",Production!E13*Prices!E13*(1-Commodities!$E13)) | F13: =IF(OR($A13="",Production!F13="",Prices!F13=""),"",Production!F13*Prices!F13*(1-Commodities!$E13)) | G13: =IF(OR($A13="",Production!G13="",Prices!G13=""),"",Production!G13*Prices!G13*(1-Commodities!$E13)) | H13: =IF(OR($A13="",Production!H13="",Prices!H13=""),"",Production!H13*Prices!H13*(1-Commodities!$E13)) | I13: =IF(OR($A13="",Production!I13="",Prices!I13=""),"",Production!I13*Prices!I13*(1-Commodities!$E13)) | J13: =IF(OR($A13="",Production!J13="",Prices!J13=""),"",Production!J13*Prices!J13*(1-Commodities!$E13))
... A41: =IF(Commodities!B41="","",Commodities!B41) | B41: =IF(Commodities!C41="","",Commodities!C41) | C41: =IF(OR($A41="",Production!C41="",Prices!C41=""),"",Production!C41*Prices!C41*(1-Commodities!$E41)) | D41: =IF(OR($A41="",Production!D41="",Prices!D41=""),"",Production!D41*Prices!D41*(1-Commodities!$E41)) | E41: =IF(OR($A41="",Production!E41="",Prices!E41=""),"",Production!E41*Prices!E41*(1-Commodities!$E41)) | F41: =IF(OR($A41="",Production!F41="",Prices!F41=""),"",Production!F41*Prices!F41*(1-Commodities!$E41)) | G41: =IF(OR($A41="",Production!G41="",Prices!G41=""),"",Production!G41*Prices!G41*(1-Commodities!$E41)) | H41: =IF(OR($A41="",Production!H41="",Prices!H41=""),"",Production!H41*Prices!H41*(1-Commodities!$E41)) | I41: =IF(OR($A41="",Production!I41="",Prices!I41=""),"",Production!I41*Prices!I41*(1-Commodities!$E41)) | J41: =IF(OR($A41="",Production!J41="",Prices!J41=""),"",Production!J41*Prices!J41*(1-Commodities!$E41))
A43: TOTAL commodity GVA | C43: =SUM(C2:C41) | D43: =SUM(D2:D41) | E43: =SUM(E2:E41) | F43: =SUM(F2:F41) | G43: =SUM(G2:G41) | H43: =SUM(H2:H41) | I43: =SUM(I2:I41) | J43: =SUM(J2:J41)

Sheet GVA_Real
A1: Commodity | B1: Sector | C1: =Production!C$1 | D1: =Production!D$1 | E1: =Production!E$1 | F1: =Production!F$1 | G1: =Production!G$1 | H1: =Production!H$1 | I1: =Production!I$1 | J1: =Production!J$1 | L1: Base-year price
A2: =IF(Commodities!B2="","",Commodities!B2) | B2: =IF(Commodities!C2="","",Commodities!C2) | C2: =IF(OR($A2="",Production!C2="",$L2=""),"",Production!C2*$L2*(1-Commodities!$E2)) | D2: =IF(OR($A2="",Production!D2="",$L2=""),"",Production!D2*$L2*(1-Commodities!$E2)) | E2: =IF(OR($A2="",Production!E2="",$L2=""),"",Production!E2*$L2*(1-Commodities!$E2)) | F2: =IF(OR($A2="",Production!F2="",$L2=""),"",Production!F2*$L2*(1-Commodities!$E2)) | G2: =IF(OR($A2="",Production!G2="",$L2=""),"",Production!G2*$L2*(1-Commodities!$E2)) | H2: =IF(OR($A2="",Production!H2="",$L2=""),"",Production!H2*$L2*(1-Commodities!$E2)) | I2: =IF(OR($A2="",Production!I2="",$L2=""),"",Production!I2*$L2*(1-Commodities!$E2)) | J2: =IF(OR($A2="",Production!J2="",$L2=""),"",Production!J2*$L2*(1-Commodities!$E2)) | L2: =IF($A2="","",IFERROR(INDEX(Prices!$C2:$J2,MATCH(Settings!$B$4,Prices!$C$1:$J$1,0)),""))
A3: =IF(Commodities!B3="","",Commodities!B3) | B3: =IF(Commodities!C3="","",Commodities!C3) | C3: =IF(OR($A3="",Production!C3="",$L3=""),"",Production!C3*$L3*(1-Commodities!$E3)) | D3: =IF(OR($A3="",Production!D3="",$L3=""),"",Production!D3*$L3*(1-Commodities!$E3)) | E3: =IF(OR($A3="",Production!E3="",$L3=""),"",Production!E3*$L3*(1-Commodities!$E3)) | F3: =IF(OR($A3="",Production!F3="",$L3=""),"",Production!F3*$L3*(1-Commodities!$E3)) | G3: =IF(OR($A3="",Production!G3="",$L3=""),"",Production!G3*$L3*(1-Commodities!$E3)) | H3: =IF(OR($A3="",Production!H3="",$L3=""),"",Production!H3*$L3*(1-Commodities!$E3)) | I3: =IF(OR($A3="",Production!I3="",$L3=""),"",Production!I3*$L3*(1-Commodities!$E3)) | J3: =IF(OR($A3="",Production!J3="",$L3=""),"",Production!J3*$L3*(1-Commodities!$E3)) | L3: =IF($A3="","",IFERROR(INDEX(Prices!$C3:$J3,MATCH(Settings!$B$4,Prices!$C$1:$J$1,0)),""))
A4: =IF(Commodities!B4="","",Commodities!B4) | B4: =IF(Commodities!C4="","",Commodities!C4) | C4: =IF(OR($A4="",Production!C4="",$L4=""),"",Production!C4*$L4*(1-Commodities!$E4)) | D4: =IF(OR($A4="",Production!D4="",$L4=""),"",Production!D4*$L4*(1-Commodities!$E4)) | E4: =IF(OR($A4="",Production!E4="",$L4=""),"",Production!E4*$L4*(1-Commodities!$E4)) | F4: =IF(OR($A4="",Production!F4="",$L4=""),"",Production!F4*$L4*(1-Commodities!$E4)) | G4: =IF(OR($A4="",Production!G4="",$L4=""),"",Production!G4*$L4*(1-Commodities!$E4)) | H4: =IF(OR($A4="",Production!H4="",$L4=""),"",Production!H4*$L4*(1-Commodities!$E4)) | I4: =IF(OR($A4="",Production!I4="",$L4=""),"",Production!I4*$L4*(1-Commodities!$E4)) | J4: =IF(OR($A4="",Production!J4="",$L4=""),"",Production!J4*$L4*(1-Commodities!$E4)) | L4: =IF($A4="","",IFERROR(INDEX(Prices!$C4:$J4,MATCH(Settings!$B$4,Prices!$C$1:$J$1,0)),""))
A5: =IF(Commodities!B5="","",Commodities!B5) | B5: =IF(Commodities!C5="","",Commodities!C5) | C5: =IF(OR($A5="",Production!C5="",$L5=""),"",Production!C5*$L5*(1-Commodities!$E5)) | D5: =IF(OR($A5="",Production!D5="",$L5=""),"",Production!D5*$L5*(1-Commodities!$E5)) | E5: =IF(OR($A5="",Production!E5="",$L5=""),"",Production!E5*$L5*(1-Commodities!$E5)) | F5: =IF(OR($A5="",Production!F5="",$L5=""),"",Production!F5*$L5*(1-Commodities!$E5)) | G5: =IF(OR($A5="",Production!G5="",$L5=""),"",Production!G5*$L5*(1-Commodities!$E5)) | H5: =IF(OR($A5="",Production!H5="",$L5=""),"",Production!H5*$L5*(1-Commodities!$E5)) | I5: =IF(OR($A5="",Production!I5="",$L5=""),"",Production!I5*$L5*(1-Commodities!$E5)) | J5: =IF(OR($A5="",Production!J5="",$L5=""),"",Production!J5*$L5*(1-Commodities!$E5)) | L5: =IF($A5="","",IFERROR(INDEX(Prices!$C5:$J5,MATCH(Settings!$B$4,Prices!$C$1:$J$1,0)),""))
A6: =IF(Commodities!B6="","",Commodities!B6) | B6: =IF(Commodities!C6="","",Commodities!C6) | C6: =IF(OR($A6="",Production!C6="",$L6=""),"",Production!C6*$L6*(1-Commodities!$E6)) | D6: =IF(OR($A6="",Production!D6="",$L6=""),"",Production!D6*$L6*(1-Commodities!$E6)) | E6: =IF(OR($A6="",Production!E6="",$L6=""),"",Production!E6*$L6*(1-Commodities!$E6)) | F6: =IF(OR($A6="",Production!F6="",$L6=""),"",Production!F6*$L6*(1-Commodities!$E6)) | G6: =IF(OR($A6="",Production!G6="",$L6=""),"",Production!G6*$L6*(1-Commodities!$E6)) | H6: =IF(OR($A6="",Production!H6="",$L6=""),"",Production!H6*$L6*(1-Commodities!$E6)) | I6: =IF(OR($A6="",Production!I6="",$L6=""),"",Production!I6*$L6*(1-Commodities!$E6)) | J6: =IF(OR($A6="",Production!J6="",$L6=""),"",Production!J6*$L6*(1-Commodities!$E6)) | L6: =IF($A6="","",IFERROR(INDEX(Prices!$C6:$J6,MATCH(Settings!$B$4,Prices!$C$1:$J$1,0)),""))
A7: =IF(Commodities!B7="","",Commodities!B7) | B7: =IF(Commodities!C7="","",Commodities!C7) | C7: =IF(OR($A7="",Production!C7="",$L7=""),"",Production!C7*$L7*(1-Commodities!$E7)) | D7: =IF(OR($A7="",Production!D7="",$L7=""),"",Production!D7*$L7*(1-Commodities!$E7)) | E7: =IF(OR($A7="",Production!E7="",$L7=""),"",Production!E7*$L7*(1-Commodities!$E7)) | F7: =IF(OR($A7="",Production!F7="",$L7=""),"",Production!F7*$L7*(1-Commodities!$E7)) | G7: =IF(OR($A7="",Production!G7="",$L7=""),"",Production!G7*$L7*(1-Commodities!$E7)) | H7: =IF(OR($A7="",Production!H7="",$L7=""),"",Production!H7*$L7*(1-Commodities!$E7)) | I7: =IF(OR($A7="",Production!I7="",$L7=""),"",Production!I7*$L7*(1-Commodities!$E7)) | J7: =IF(OR($A7="",Production!J7="",$L7=""),"",Production!J7*$L7*(1-Commodities!$E7)) | L7: =IF($A7="","",IFERROR(INDEX(Prices!$C7:$J7,MATCH(Settings!$B$4,Prices!$C$1:$J$1,0)),""))
A8: =IF(Commodities!B8="","",Commodities!B8) | B8: =IF(Commodities!C8="","",Commodities!C8) | C8: =IF(OR($A8="",Production!C8="",$L8=""),"",Production!C8*$L8*(1-Commodities!$E8)) | D8: =IF(OR($A8="",Production!D8="",$L8=""),"",Production!D8*$L8*(1-Commodities!$E8)) | E8: =IF(OR($A8="",Production!E8="",$L8=""),"",Production!E8*$L8*(1-Commodities!$E8)) | F8: =IF(OR($A8="",Production!F8="",$L8=""),"",Production!F8*$L8*(1-Commodities!$E8)) | G8: =IF(OR($A8="",Production!G8="",$L8=""),"",Production!G8*$L8*(1-Commodities!$E8)) | H8: =IF(OR($A8="",Production!H8="",$L8=""),"",Production!H8*$L8*(1-Commodities!$E8)) | I8: =IF(OR($A8="",Production!I8="",$L8=""),"",Production!I8*$L8*(1-Commodities!$E8)) | J8: =IF(OR($A8="",Production!J8="",$L8=""),"",Production!J8*$L8*(1-Commodities!$E8)) | L8: =IF($A8="","",IFERROR(INDEX(Prices!$C8:$J8,MATCH(Settings!$B$4,Prices!$C$1:$J$1,0)),""))
A9: =IF(Commodities!B9="","",Commodities!B9) | B9: =IF(Commodities!C9="","",Commodities!C9) | C9: =IF(OR($A9="",Production!C9="",$L9=""),"",Production!C9*$L9*(1-Commodities!$E9)) | D9: =IF(OR($A9="",Production!D9="",$L9=""),"",Production!D9*$L9*(1-Commodities!$E9)) | E9: =IF(OR($A9="",Production!E9="",$L9=""),"",Production!E9*$L9*(1-Commodities!$E9)) | F9: =IF(OR($A9="",Production!F9="",$L9=""),"",Production!F9*$L9*(1-Commodities!$E9)) | G9: =IF(OR($A9="",Production!G9="",$L9=""),"",Production!G9*$L9*(1-Commodities!$E9)) | H9: =IF(OR($A9="",Production!H9="",$L9=""),"",Production!H9*$L9*(1-Commodities!$E9)) | I9: =IF(OR($A9="",Production!I9="",$L9=""),"",Production!I9*$L9*(1-Commodities!$E9)) | J9: =IF(OR($A9="",Production!J9="",$L9=""),"",Production!J9*$L9*(1-Commodities!$E9)) | L9: =IF($A9="","",IFERROR(INDEX(Prices!$C9:$J9,MATCH(Settings!$B$4,Prices!$C$1:$J$1,0)),""))
A10: =IF(Commodities!B10="","",Commodities!B10) | B10: =IF(Commodities!C10="","",Commodities!C10) | C10: =IF(OR($A10="",Production!C10="",$L10=""),"",Production!C10*$L10*(1-Commodities!$E10)) | D10: =IF(OR($A10="",Production!D10="",$L10=""),"",Production!D10*$L10*(1-Commodities!$E10)) | E10: =IF(OR($A10="",Production!E10="",$L10=""),"",Production!E10*$L10*(1-Commodities!$E10)) | F10: =IF(OR($A10="",Production!F10="",$L10=""),"",Production!F10*$L10*(1-Commodities!$E10)) | G10: =IF(OR($A10="",Production!G10="",$L10=""),"",Production!G10*$L10*(1-Commodities!$E10)) | H10: =IF(OR($A10="",Production!H10="",$L10=""),"",Production!H10*$L10*(1-Commodities!$E10)) | I10: =IF(OR($A10="",Production!I10="",$L10=""),"",Production!I10*$L10*(1-Commodities!$E10)) | J10: =IF(OR($A10="",Production!J10="",$L10=""),"",Production!J10*$L10*(1-Commodities!$E10)) | L10: =IF($A10="","",IFERROR(INDEX(Prices!$C10:$J10,MATCH(Settings!$B$4,Prices!$C$1:$J$1,0)),""))
A11: =IF(Commodities!B11="","",Commodities!B11) | B11: =IF(Commodities!C11="","",Commodities!C11) | C11: =IF(OR($A11="",Production!C11="",$L11=""),"",Production!C11*$L11*(1-Commodities!$E11)) | D11: =IF(OR($A11="",Production!D11="",$L11=""),"",Production!D11*$L11*(1-Commodities!$E11)) | E11: =IF(OR($A11="",Production!E11="",$L11=""),"",Production!E11*$L11*(1-Commodities!$E11)) | F11: =IF(OR($A11="",Production!F11="",$L11=""),"",Production!F11*$L11*(1-Commodities!$E11)) | G11: =IF(OR($A11="",Production!G11="",$L11=""),"",Production!G11*$L11*(1-Commodities!$E11)) | H11: =IF(OR($A11="",Production!H11="",$L11=""),"",Production!H11*$L11*(1-Commodities!$E11)) | I11: =IF(OR($A11="",Production!I11="",$L11=""),"",Production!I11*$L11*(1-Commodities!$E11)) | J11: =IF(OR($A11="",Production!J11="",$L11=""),"",Production!J11*$L11*(1-Commodities!$E11)) | L11: =IF($A11="","",IFERROR(INDEX(Prices!$C11:$J11,MATCH(Settings!$B$4,Prices!$C$1:$J$1,0)),""))
A12: =IF(Commodities!B12="","",Commodities!B12) | B12: =IF(Commodities!C12="","",Commodities!C12) | C12: =IF(OR($A12="",Production!C12="",$L12=""),"",Production!C12*$L12*(1-Commodities!$E12)) | D12: =IF(OR($A12="",Production!D12="",$L12=""),"",Production!D12*$L12*(1-Commodities!$E12)) | E12: =IF(OR($A12="",Production!E12="",$L12=""),"",Production!E12*$L12*(1-Commodities!$E12)) | F12: =IF(OR($A12="",Production!F12="",$L12=""),"",Production!F12*$L12*(1-Commodities!$E12)) | G12: =IF(OR($A12="",Production!G12="",$L12=""),"",Production!G12*$L12*(1-Commodities!$E12)) | H12: =IF(OR($A12="",Production!H12="",$L12=""),"",Production!H12*$L12*(1-Commodities!$E12)) | I12: =IF(OR($A12="",Production!I12="",$L12=""),"",Production!I12*$L12*(1-Commodities!$E12)) | J12: =IF(OR($A12="",Production!J12="",$L12=""),"",Production!J12*$L12*(1-Commodities!$E12)) | L12: =IF($A12="","",IFERROR(INDEX(Prices!$C12:$J12,MATCH(Settings!$B$4,Prices!$C$1:$J$1,0)),""))
A13: =IF(Commodities!B13="","",Commodities!B13) | B13: =IF(Commodities!C13="","",Commodities!C13) | C13: =IF(OR($A13="",Production!C13="",$L13=""),"",Production!C13*$L13*(1-Commodities!$E13)) | D13: =IF(OR($A13="",Production!D13="",$L13=""),"",Production!D13*$L13*(1-Commodities!$E13)) | E13: =IF(OR($A13="",Production!E13="",$L13=""),"",Production!E13*$L13*(1-Commodities!$E13)) | F13: =IF(OR($A13="",Production!F13="",$L13=""),"",Production!F13*$L13*(1-Commodities!$E13)) | G13: =IF(OR($A13="",Production!G13="",$L13=""),"",Production!G13*$L13*(1-Commodities!$E13)) | H13: =IF(OR($A13="",Production!H13="",$L13=""),"",Production!H13*$L13*(1-Commodities!$E13)) | I13: =IF(OR($A13="",Production!I13="",$L13=""),"",Production!I13*$L13*(1-Commodities!$E13)) | J13: =IF(OR($A13="",Production!J13="",$L13=""),"",Production!J13*$L13*(1-Commodities!$E13)) | L13: =IF($A13="","",IFERROR(INDEX(Prices!$C13:$J13,MATCH(Settings!$B$4,Prices!$C$1:$J$1,0)),""))
... A41: =IF(Commodities!B41="","",Commodities!B41) | B41: =IF(Commodities!C41="","",Commodities!C41) | C41: =IF(OR($A41="",Production!C41="",$L41=""),"",Production!C41*$L41*(1-Commodities!$E41)) | D41: =IF(OR($A41="",Production!D41="",$L41=""),"",Production!D41*$L41*(1-Commodities!$E41)) | E41: =IF(OR($A41="",Production!E41="",$L41=""),"",Production!E41*$L41*(1-Commodities!$E41)) | F41: =IF(OR($A41="",Production!F41="",$L41=""),"",Production!F41*$L41*(1-Commodities!$E41)) | G41: =IF(OR($A41="",Production!G41="",$L41=""),"",Production!G41*$L41*(1-Commodities!$E41)) | H41: =IF(OR($A41="",Production!H41="",$L41=""),"",Production!H41*$L41*(1-Commodities!$E41)) | I41: =IF(OR($A41="",Production!I41="",$L41=""),"",Production!I41*$L41*(1-Commodities!$E41)) | J41: =IF(OR($A41="",Production!J41="",$L41=""),"",Production!J41*$L41*(1-Commodities!$E41)) | L41: =IF($A41="","",IFERROR(INDEX(Prices!$C41:$J41,MATCH(Settings!$B$4,Prices!$C$1:$J$1,0)),""))
A43: TOTAL commodity GVA | C43: =SUM(C2:C41) | D43: =SUM(D2:D41) | E43: =SUM(E2:E41) | F43: =SUM(F2:F41) | G43: =SUM(G2:G41) | H43: =SUM(H2:H41) | I43: =SUM(I2:I41) | J43: =SUM(J2:J41)

Sheet GDP_Summary
A1: GDP — PRODUCTION APPROACH
A2: =CONCATENATE("Values in ",Settings!B6,". Constant prices of base year ",Settings!B4,".")
A3: Industry / aggregate | C3: =Production!C$1 | D3: =Production!D$1 | E3: =Production!E$1 | F3: =Production!F$1 | G3: =Production!G$1 | H3: =Production!H$1 | I3: =Production!I$1 | J3: =Production!J$1
A4: NOMINAL — current prices
A5: Agriculture & Livestock | C5: =SUMIFS(GVA_Nominal!C$2:C$41,GVA_Nominal!$B$2:$B$41,$A5) | D5: =SUMIFS(GVA_Nominal!D$2:D$41,GVA_Nominal!$B$2:$B$41,$A5) | E5: =SUMIFS(GVA_Nominal!E$2:E$41,GVA_Nominal!$B$2:$B$41,$A5) | F5: =SUMIFS(GVA_Nominal!F$2:F$41,GVA_Nominal!$B$2:$B$41,$A5) | G5: =SUMIFS(GVA_Nominal!G$2:G$41,GVA_Nominal!$B$2:$B$41,$A5) | H5: =SUMIFS(GVA_Nominal!H$2:H$41,GVA_Nominal!$B$2:$B$41,$A5) | I5: =SUMIFS(GVA_Nominal!I$2:I$41,GVA_Nominal!$B$2:$B$41,$A5) | J5: =SUMIFS(GVA_Nominal!J$2:J$41,GVA_Nominal!$B$2:$B$41,$A5)
A6: Forestry | C6: =SUMIFS(GVA_Nominal!C$2:C$41,GVA_Nominal!$B$2:$B$41,$A6) | D6: =SUMIFS(GVA_Nominal!D$2:D$41,GVA_Nominal!$B$2:$B$41,$A6) | E6: =SUMIFS(GVA_Nominal!E$2:E$41,GVA_Nominal!$B$2:$B$41,$A6) | F6: =SUMIFS(GVA_Nominal!F$2:F$41,GVA_Nominal!$B$2:$B$41,$A6) | G6: =SUMIFS(GVA_Nominal!G$2:G$41,GVA_Nominal!$B$2:$B$41,$A6) | H6: =SUMIFS(GVA_Nominal!H$2:H$41,GVA_Nominal!$B$2:$B$41,$A6) | I6: =SUMIFS(GVA_Nominal!I$2:I$41,GVA_Nominal!$B$2:$B$41,$A6) | J6: =SUMIFS(GVA_Nominal!J$2:J$41,GVA_Nominal!$B$2:$B$41,$A6)
A7: Fishing | C7: =SUMIFS(GVA_Nominal!C$2:C$41,GVA_Nominal!$B$2:$B$41,$A7) | D7: =SUMIFS(GVA_Nominal!D$2:D$41,GVA_Nominal!$B$2:$B$41,$A7) | E7: =SUMIFS(GVA_Nominal!E$2:E$41,GVA_Nominal!$B$2:$B$41,$A7) | F7: =SUMIFS(GVA_Nominal!F$2:F$41,GVA_Nominal!$B$2:$B$41,$A7) | G7: =SUMIFS(GVA_Nominal!G$2:G$41,GVA_Nominal!$B$2:$B$41,$A7) | H7: =SUMIFS(GVA_Nominal!H$2:H$41,GVA_Nominal!$B$2:$B$41,$A7) | I7: =SUMIFS(GVA_Nominal!I$2:I$41,GVA_Nominal!$B$2:$B$41,$A7) | J7: =SUMIFS(GVA_Nominal!J$2:J$41,GVA_Nominal!$B$2:$B$41,$A7)
A8: Mining & Quarrying | C8: =SUMIFS(GVA_Nominal!C$2:C$41,GVA_Nominal!$B$2:$B$41,$A8) | D8: =SUMIFS(GVA_Nominal!D$2:D$41,GVA_Nominal!$B$2:$B$41,$A8) | E8: =SUMIFS(GVA_Nominal!E$2:E$41,GVA_Nominal!$B$2:$B$41,$A8) | F8: =SUMIFS(GVA_Nominal!F$2:F$41,GVA_Nominal!$B$2:$B$41,$A8) | G8: =SUMIFS(GVA_Nominal!G$2:G$41,GVA_Nominal!$B$2:$B$41,$A8) | H8: =SUMIFS(GVA_Nominal!H$2:H$41,GVA_Nominal!$B$2:$B$41,$A8) | I8: =SUMIFS(GVA_Nominal!I$2:I$41,GVA_Nominal!$B$2:$B$41,$A8) | J8: =SUMIFS(GVA_Nominal!J$2:J$41,GVA_Nominal!$B$2:$B$41,$A8)
A9: Manufacturing | C9: =IF(Other_Sectors!C4="",0,Other_Sectors!C4) | D9: =IF(Other_Sectors!D4="",0,Other_Sectors!D4) | E9: =IF(Other_Sectors!E4="",0,Other_Sectors!E4) | F9: =IF(Other_Sectors!F4="",0,Other_Sectors!F4) | G9: =IF(Other_Sectors!G4="",0,Other_Sectors!G4) | H9: =IF(Other_Sectors!H4="",0,Other_Sectors!H4) | I9: =IF(Other_Sectors!I4="",0,Other_Sectors!I4) | J9: =IF(Other_Sectors!J4="",0,Other_Sectors!J4)
A10: Electricity & Water | C10: =IF(Other_Sectors!C5="",0,Other_Sectors!C5) | D10: =IF(Other_Sectors!D5="",0,Other_Sectors!D5) | E10: =IF(Other_Sectors!E5="",0,Other_Sectors!E5) | F10: =IF(Other_Sectors!F5="",0,Other_Sectors!F5) | G10: =IF(Other_Sectors!G5="",0,Other_Sectors!G5) | H10: =IF(Other_Sectors!H5="",0,Other_Sectors!H5) | I10: =IF(Other_Sectors!I5="",0,Other_Sectors!I5) | J10: =IF(Other_Sectors!J5="",0,Other_Sectors!J5)
A11: Construction | C11: =IF(Other_Sectors!C6="",0,Other_Sectors!C6) | D11: =IF(Other_Sectors!D6="",0,Other_Sectors!D6) | E11: =IF(Other_Sectors!E6="",0,Other_Sectors!E6) | F11: =IF(Other_Sectors!F6="",0,Other_Sectors!F6) | G11: =IF(Other_Sectors!G6="",0,Other_Sectors!G6) | H11: =IF(Other_Sectors!H6="",0,Other_Sectors!H6) | I11: =IF(Other_Sectors!I6="",0,Other_Sectors!I6) | J11: =IF(Other_Sectors!J6="",0,Other_Sectors!J6)
A12: Wholesale & Retail Trade | C12: =IF(Other_Sectors!C7="",0,Other_Sectors!C7) | D12: =IF(Other_Sectors!D7="",0,Other_Sectors!D7) | E12: =IF(Other_Sectors!E7="",0,Other_Sectors!E7) | F12: =IF(Other_Sectors!F7="",0,Other_Sectors!F7) | G12: =IF(Other_Sectors!G7="",0,Other_Sectors!G7) | H12: =IF(Other_Sectors!H7="",0,Other_Sectors!H7) | I12: =IF(Other_Sectors!I7="",0,Other_Sectors!I7) | J12: =IF(Other_Sectors!J7="",0,Other_Sectors!J7)
A13: Transport & Storage | C13: =IF(Other_Sectors!C8="",0,Other_Sectors!C8) | D13: =IF(Other_Sectors!D8="",0,Other_Sectors!D8) | E13: =IF(Other_Sectors!E8="",0,Other_Sectors!E8) | F13: =IF(Other_Sectors!F8="",0,Other_Sectors!F8) | G13: =IF(Other_Sectors!G8="",0,Other_Sectors!G8) | H13: =IF(Other_Sectors!H8="",0,Other_Sectors!H8) | I13: =IF(Other_Sectors!I8="",0,Other_Sectors!I8) | J13: =IF(Other_Sectors!J8="",0,Other_Sectors!J8)
A14: Accommodation & Food Services | C14: =IF(Other_Sectors!C9="",0,Other_Sectors!C9) | D14: =IF(Other_Sectors!D9="",0,Other_Sectors!D9) | E14: =IF(Other_Sectors!E9="",0,Other_Sectors!E9) | F14: =IF(Other_Sectors!F9="",0,Other_Sectors!F9) | G14: =IF(Other_Sectors!G9="",0,Other_Sectors!G9) | H14: =IF(Other_Sectors!H9="",0,Other_Sectors!H9) | I14: =IF(Other_Sectors!I9="",0,Other_Sectors!I9) | J14: =IF(Other_Sectors!J9="",0,Other_Sectors!J9)
A15: Information & Communication | C15: =IF(Other_Sectors!C10="",0,Other_Sectors!C10) | D15: =IF(Other_Sectors!D10="",0,Other_Sectors!D10) | E15: =IF(Other_Sectors!E10="",0,Other_Sectors!E10) | F15: =IF(Other_Sectors!F10="",0,Other_Sectors!F10) | G15: =IF(Other_Sectors!G10="",0,Other_Sectors!G10) | H15: =IF(Other_Sectors!H10="",0,Other_Sectors!H10) | I15: =IF(Other_Sectors!I10="",0,Other_Sectors!I10) | J15: =IF(Other_Sectors!J10="",0,Other_Sectors!J10)
A16: Financial & Insurance Services | C16: =IF(Other_Sectors!C11="",0,Other_Sectors!C11) | D16: =IF(Other_Sectors!D11="",0,Other_Sectors!D11) | E16: =IF(Other_Sectors!E11="",0,Other_Sectors!E11) | F16: =IF(Other_Sectors!F11="",0,Other_Sectors!F11) | G16: =IF(Other_Sectors!G11="",0,Other_Sectors!G11) | H16: =IF(Other_Sectors!H11="",0,Other_Sectors!H11) | I16: =IF(Other_Sectors!I11="",0,Other_Sectors!I11) | J16: =IF(Other_Sectors!J11="",0,Other_Sectors!J11)
A17: Real Estate | C17: =IF(Other_Sectors!C12="",0,Other_Sectors!C12) | D17: =IF(Other_Sectors!D12="",0,Other_Sectors!D12) | E17: =IF(Other_Sectors!E12="",0,Other_Sectors!E12) | F17: =IF(Other_Sectors!F12="",0,Other_Sectors!F12) | G17: =IF(Other_Sectors!G12="",0,Other_Sectors!G12) | H17: =IF(Other_Sectors!H12="",0,Other_Sectors!H12) | I17: =IF(Other_Sectors!I12="",0,Other_Sectors!I12) | J17: =IF(Other_Sectors!J12="",0,Other_Sectors!J12)
A18: Public Administration | C18: =IF(Other_Sectors!C13="",0,Other_Sectors!C13) | D18: =IF(Other_Sectors!D13="",0,Other_Sectors!D13) | E18: =IF(Other_Sectors!E13="",0,Other_Sectors!E13) | F18: =IF(Other_Sectors!F13="",0,Other_Sectors!F13) | G18: =IF(Other_Sectors!G13="",0,Other_Sectors!G13) | H18: =IF(Other_Sectors!H13="",0,Other_Sectors!H13) | I18: =IF(Other_Sectors!I13="",0,Other_Sectors!I13) | J18: =IF(Other_Sectors!J13="",0,Other_Sectors!J13)
A19: Education & Health | C19: =IF(Other_Sectors!C14="",0,Other_Sectors!C14) | D19: =IF(Other_Sectors!D14="",0,Other_Sectors!D14) | E19: =IF(Other_Sectors!E14="",0,Other_Sectors!E14) | F19: =IF(Other_Sectors!F14="",0,Other_Sectors!F14) | G19: =IF(Other_Sectors!G14="",0,Other_Sectors!G14) | H19: =IF(Other_Sectors!H14="",0,Other_Sectors!H14) | I19: =IF(Other_Sectors!I14="",0,Other_Sectors!I14) | J19: =IF(Other_Sectors!J14="",0,Other_Sectors!J14)
A20: Other Services | C20: =IF(Other_Sectors!C15="",0,Other_Sectors!C15) | D20: =IF(Other_Sectors!D15="",0,Other_Sectors!D15) | E20: =IF(Other_Sectors!E15="",0,Other_Sectors!E15) | F20: =IF(Other_Sectors!F15="",0,Other_Sectors!F15) | G20: =IF(Other_Sectors!G15="",0,Other_Sectors!G15) | H20: =IF(Other_Sectors!H15="",0,Other_Sectors!H15) | I20: =IF(Other_Sectors!I15="",0,Other_Sectors!I15) | J20: =IF(Other_Sectors!J15="",0,Other_Sectors!J15)
A21: Gross Value Added at basic prices | C21: =SUM(C5:C20) | D21: =SUM(D5:D20) | E21: =SUM(E5:E20) | F21: =SUM(F5:F20) | G21: =SUM(G5:G20) | H21: =SUM(H5:H20) | I21: =SUM(I5:I20) | J21: =SUM(J5:J20)
A22: Taxes less subsidies on products [input]
A23: GDP at market prices — NOMINAL | C23: =IF(C21=0,"",C21+IF(C22="",0,C22)) | D23: =IF(D21=0,"",D21+IF(D22="",0,D22)) | E23: =IF(E21=0,"",E21+IF(E22="",0,E22)) | F23: =IF(F21=0,"",F21+IF(F22="",0,F22)) | G23: =IF(G21=0,"",G21+IF(G22="",0,G22)) | H23: =IF(H21=0,"",H21+IF(H22="",0,H22)) | I23: =IF(I21=0,"",I21+IF(I22="",0,I22)) | J23: =IF(J21=0,"",J21+IF(J22="",0,J22))
A25: REAL — constant base-year prices
A26: Agriculture & Livestock | C26: =SUMIFS(GVA_Real!C$2:C$41,GVA_Real!$B$2:$B$41,$A26) | D26: =SUMIFS(GVA_Real!D$2:D$41,GVA_Real!$B$2:$B$41,$A26) | E26: =SUMIFS(GVA_Real!E$2:E$41,GVA_Real!$B$2:$B$41,$A26) | F26: =SUMIFS(GVA_Real!F$2:F$41,GVA_Real!$B$2:$B$41,$A26) | G26: =SUMIFS(GVA_Real!G$2:G$41,GVA_Real!$B$2:$B$41,$A26) | H26: =SUMIFS(GVA_Real!H$2:H$41,GVA_Real!$B$2:$B$41,$A26) | I26: =SUMIFS(GVA_Real!I$2:I$41,GVA_Real!$B$2:$B$41,$A26) | J26: =SUMIFS(GVA_Real!J$2:J$41,GVA_Real!$B$2:$B$41,$A26)
A27: Forestry | C27: =SUMIFS(GVA_Real!C$2:C$41,GVA_Real!$B$2:$B$41,$A27) | D27: =SUMIFS(GVA_Real!D$2:D$41,GVA_Real!$B$2:$B$41,$A27) | E27: =SUMIFS(GVA_Real!E$2:E$41,GVA_Real!$B$2:$B$41,$A27) | F27: =SUMIFS(GVA_Real!F$2:F$41,GVA_Real!$B$2:$B$41,$A27) | G27: =SUMIFS(GVA_Real!G$2:G$41,GVA_Real!$B$2:$B$41,$A27) | H27: =SUMIFS(GVA_Real!H$2:H$41,GVA_Real!$B$2:$B$41,$A27) | I27: =SUMIFS(GVA_Real!I$2:I$41,GVA_Real!$B$2:$B$41,$A27) | J27: =SUMIFS(GVA_Real!J$2:J$41,GVA_Real!$B$2:$B$41,$A27)
A28: Fishing | C28: =SUMIFS(GVA_Real!C$2:C$41,GVA_Real!$B$2:$B$41,$A28) | D28: =SUMIFS(GVA_Real!D$2:D$41,GVA_Real!$B$2:$B$41,$A28) | E28: =SUMIFS(GVA_Real!E$2:E$41,GVA_Real!$B$2:$B$41,$A28) | F28: =SUMIFS(GVA_Real!F$2:F$41,GVA_Real!$B$2:$B$41,$A28) | G28: =SUMIFS(GVA_Real!G$2:G$41,GVA_Real!$B$2:$B$41,$A28) | H28: =SUMIFS(GVA_Real!H$2:H$41,GVA_Real!$B$2:$B$41,$A28) | I28: =SUMIFS(GVA_Real!I$2:I$41,GVA_Real!$B$2:$B$41,$A28) | J28: =SUMIFS(GVA_Real!J$2:J$41,GVA_Real!$B$2:$B$41,$A28)
A29: Mining & Quarrying | C29: =SUMIFS(GVA_Real!C$2:C$41,GVA_Real!$B$2:$B$41,$A29) | D29: =SUMIFS(GVA_Real!D$2:D$41,GVA_Real!$B$2:$B$41,$A29) | E29: =SUMIFS(GVA_Real!E$2:E$41,GVA_Real!$B$2:$B$41,$A29) | F29: =SUMIFS(GVA_Real!F$2:F$41,GVA_Real!$B$2:$B$41,$A29) | G29: =SUMIFS(GVA_Real!G$2:G$41,GVA_Real!$B$2:$B$41,$A29) | H29: =SUMIFS(GVA_Real!H$2:H$41,GVA_Real!$B$2:$B$41,$A29) | I29: =SUMIFS(GVA_Real!I$2:I$41,GVA_Real!$B$2:$B$41,$A29) | J29: =SUMIFS(GVA_Real!J$2:J$41,GVA_Real!$B$2:$B$41,$A29)
A30: Manufacturing | C30: =IF(Other_Sectors!C19="",0,Other_Sectors!C19) | D30: =IF(Other_Sectors!D19="",0,Other_Sectors!D19) | E30: =IF(Other_Sectors!E19="",0,Other_Sectors!E19) | F30: =IF(Other_Sectors!F19="",0,Other_Sectors!F19) | G30: =IF(Other_Sectors!G19="",0,Other_Sectors!G19) | H30: =IF(Other_Sectors!H19="",0,Other_Sectors!H19) | I30: =IF(Other_Sectors!I19="",0,Other_Sectors!I19) | J30: =IF(Other_Sectors!J19="",0,Other_Sectors!J19)
A31: Electricity & Water | C31: =IF(Other_Sectors!C20="",0,Other_Sectors!C20) | D31: =IF(Other_Sectors!D20="",0,Other_Sectors!D20) | E31: =IF(Other_Sectors!E20="",0,Other_Sectors!E20) | F31: =IF(Other_Sectors!F20="",0,Other_Sectors!F20) | G31: =IF(Other_Sectors!G20="",0,Other_Sectors!G20) | H31: =IF(Other_Sectors!H20="",0,Other_Sectors!H20) | I31: =IF(Other_Sectors!I20="",0,Other_Sectors!I20) | J31: =IF(Other_Sectors!J20="",0,Other_Sectors!J20)
A32: Construction | C32: =IF(Other_Sectors!C21="",0,Other_Sectors!C21) | D32: =IF(Other_Sectors!D21="",0,Other_Sectors!D21) | E32: =IF(Other_Sectors!E21="",0,Other_Sectors!E21) | F32: =IF(Other_Sectors!F21="",0,Other_Sectors!F21) | G32: =IF(Other_Sectors!G21="",0,Other_Sectors!G21) | H32: =IF(Other_Sectors!H21="",0,Other_Sectors!H21) | I32: =IF(Other_Sectors!I21="",0,Other_Sectors!I21) | J32: =IF(Other_Sectors!J21="",0,Other_Sectors!J21)
A33: Wholesale & Retail Trade | C33: =IF(Other_Sectors!C22="",0,Other_Sectors!C22) | D33: =IF(Other_Sectors!D22="",0,Other_Sectors!D22) | E33: =IF(Other_Sectors!E22="",0,Other_Sectors!E22) | F33: =IF(Other_Sectors!F22="",0,Other_Sectors!F22) | G33: =IF(Other_Sectors!G22="",0,Other_Sectors!G22) | H33: =IF(Other_Sectors!H22="",0,Other_Sectors!H22) | I33: =IF(Other_Sectors!I22="",0,Other_Sectors!I22) | J33: =IF(Other_Sectors!J22="",0,Other_Sectors!J22)
A34: Transport & Storage | C34: =IF(Other_Sectors!C23="",0,Other_Sectors!C23) | D34: =IF(Other_Sectors!D23="",0,Other_Sectors!D23) | E34: =IF(Other_Sectors!E23="",0,Other_Sectors!E23) | F34: =IF(Other_Sectors!F23="",0,Other_Sectors!F23) | G34: =IF(Other_Sectors!G23="",0,Other_Sectors!G23) | H34: =IF(Other_Sectors!H23="",0,Other_Sectors!H23) | I34: =IF(Other_Sectors!I23="",0,Other_Sectors!I23) | J34: =IF(Other_Sectors!J23="",0,Other_Sectors!J23)
A35: Accommodation & Food Services | C35: =IF(Other_Sectors!C24="",0,Other_Sectors!C24) | D35: =IF(Other_Sectors!D24="",0,Other_Sectors!D24) | E35: =IF(Other_Sectors!E24="",0,Other_Sectors!E24) | F35: =IF(Other_Sectors!F24="",0,Other_Sectors!F24) | G35: =IF(Other_Sectors!G24="",0,Other_Sectors!G24) | H35: =IF(Other_Sectors!H24="",0,Other_Sectors!H24) | I35: =IF(Other_Sectors!I24="",0,Other_Sectors!I24) | J35: =IF(Other_Sectors!J24="",0,Other_Sectors!J24)
A36: Information & Communication | C36: =IF(Other_Sectors!C25="",0,Other_Sectors!C25) | D36: =IF(Other_Sectors!D25="",0,Other_Sectors!D25) | E36: =IF(Other_Sectors!E25="",0,Other_Sectors!E25) | F36: =IF(Other_Sectors!F25="",0,Other_Sectors!F25) | G36: =IF(Other_Sectors!G25="",0,Other_Sectors!G25) | H36: =IF(Other_Sectors!H25="",0,Other_Sectors!H25) | I36: =IF(Other_Sectors!I25="",0,Other_Sectors!I25) | J36: =IF(Other_Sectors!J25="",0,Other_Sectors!J25)
A37: Financial & Insurance Services | C37: =IF(Other_Sectors!C26="",0,Other_Sectors!C26) | D37: =IF(Other_Sectors!D26="",0,Other_Sectors!D26) | E37: =IF(Other_Sectors!E26="",0,Other_Sectors!E26) | F37: =IF(Other_Sectors!F26="",0,Other_Sectors!F26) | G37: =IF(Other_Sectors!G26="",0,Other_Sectors!G26) | H37: =IF(Other_Sectors!H26="",0,Other_Sectors!H26) | I37: =IF(Other_Sectors!I26="",0,Other_Sectors!I26) | J37: =IF(Other_Sectors!J26="",0,Other_Sectors!J26)
A38: Real Estate | C38: =IF(Other_Sectors!C27="",0,Other_Sectors!C27) | D38: =IF(Other_Sectors!D27="",0,Other_Sectors!D27) | E38: =IF(Other_Sectors!E27="",0,Other_Sectors!E27) | F38: =IF(Other_Sectors!F27="",0,Other_Sectors!F27) | G38: =IF(Other_Sectors!G27="",0,Other_Sectors!G27) | H38: =IF(Other_Sectors!H27="",0,Other_Sectors!H27) | I38: =IF(Other_Sectors!I27="",0,Other_Sectors!I27) | J38: =IF(Other_Sectors!J27="",0,Other_Sectors!J27)
A39: Public Administration | C39: =IF(Other_Sectors!C28="",0,Other_Sectors!C28) | D39: =IF(Other_Sectors!D28="",0,Other_Sectors!D28) | E39: =IF(Other_Sectors!E28="",0,Other_Sectors!E28) | F39: =IF(Other_Sectors!F28="",0,Other_Sectors!F28) | G39: =IF(Other_Sectors!G28="",0,Other_Sectors!G28) | H39: =IF(Other_Sectors!H28="",0,Other_Sectors!H28) | I39: =IF(Other_Sectors!I28="",0,Other_Sectors!I28) | J39: =IF(Other_Sectors!J28="",0,Other_Sectors!J28)
A40: Education & Health | C40: =IF(Other_Sectors!C29="",0,Other_Sectors!C29) | D40: =IF(Other_Sectors!D29="",0,Other_Sectors!D29) | E40: =IF(Other_Sectors!E29="",0,Other_Sectors!E29) | F40: =IF(Other_Sectors!F29="",0,Other_Sectors!F29) | G40: =IF(Other_Sectors!G29="",0,Other_Sectors!G29) | H40: =IF(Other_Sectors!H29="",0,Other_Sectors!H29) | I40: =IF(Other_Sectors!I29="",0,Other_Sectors!I29) | J40: =IF(Other_Sectors!J29="",0,Other_Sectors!J29)
A41: Other Services | C41: =IF(Other_Sectors!C30="",0,Other_Sectors!C30) | D41: =IF(Other_Sectors!D30="",0,Other_Sectors!D30) | E41: =IF(Other_Sectors!E30="",0,Other_Sectors!E30) | F41: =IF(Other_Sectors!F30="",0,Other_Sectors!F30) | G41: =IF(Other_Sectors!G30="",0,Other_Sectors!G30) | H41: =IF(Other_Sectors!H30="",0,Other_Sectors!H30) | I41: =IF(Other_Sectors!I30="",0,Other_Sectors!I30) | J41: =IF(Other_Sectors!J30="",0,Other_Sectors!J30)
...

Sheet Dashboard
A1: DASHBOARD
