Workbook

Sheet Guide
A1: GDP Model - Analysis Dashboard (2025 estimate)
A2: A simple companion to GDP_model_forecasting_2025.xlsx and the 'GDP Model - Theory and Forecast' slides
A4: WHAT THIS WORKBOOK DOES
A5: It rebuilds the 2025 constant-price (real) GDP estimate step by step, using the same method as the forecasting model, so you can see where every number comes from. 2024 is the base (actual NSO numbers); 2025 is estimated from commodity-board volumes, government wages and judgement growth rates.
A7: THE THREE WAYS TO MEASURE GDP (slide 2)
A8: Expenditure approach | B8: GDP = C + I + G + X - M (household & government consumption, investment, exports less imports)
A9: Income approach | B9: GDP = wages & salaries + business profits + self-employed income + taxes on products - subsidies
A10: Production approach <- this model | B10: GDP = sum over industries of (output - intermediate inputs) + taxes on products - subsidies
A12: HOW THE FORECAST WORKS (slides 5-7)
A13: Key idea | B13: Intermediate input shares are held constant, so real (constant-price) growth of value added = growth in physical volume.
A14: Resource sector | B14: Real GVA 2025 = Real GVA 2024 x (2025 volume / 2024 volume), per commodity, using Dept. of Treasury volumes. Nominal GVA also multiplies by the commodity price growth ratio.
A15: Agriculture, forestry & fishing | B15: Formal commodities grow with their industry volumes (cocoa, coffee, palm oil, logs, fish...). Informal activity (food gardens, betel nut, informal fishing) grows with population.
A16: Public admin, health, education | B16: Nominal growth = growth in government compensation of employees. Deflator growth = government wage growth. Real growth = nominal growth / deflator growth.
A17: All other sectors | B17: Default: grow with population (2.6%). Override with a judgement growth rate where you have evidence (comments from the model are shown).
A18: Real -> nominal GDP | B18: Nominal GDP = real GDP x GDP deflator (IPD) / 100.
A19: Contribution to growth | B19: Sector contribution (percentage points) = change in sector real GVA / total real GDP last year. Contributions add up to GDP growth.
A21: HOW TO USE IT
A22: 1. Dashboard | B22: Headline numbers, contributions to growth and charts. Read this first.
A23: 2. Resource | B23: Paste new DoT production numbers into the red cells; resource GVA updates automatically.
A24: 3. AFF | B24: Commodity-board volumes for agriculture, forestry and fishing; informal growth assumption.
A25: 4. Public_Admin | B25: Government compensation of employees and wage growth.
A26: 5. Other_Sectors | B26: Type a judgement growth rate in the yellow column to override the population default. Try it and watch the Dashboard change.
A27: 6. History | B27: Actual GDP 1993-2024 series (2006 onward shown) with the 2025 estimate appended.
A28: 7. Model_Check | B28: Issues found in GDP_model_forecasting_2025.xlsx that stop its 2025 column from calculating.
A30: COLOUR CODE (same as the forecasting model)
A31: Red numbers | B31: Hard-coded data (NSO national accounts, DoT production, commodity boards)
A32: Blue numbers | B32: Assumptions (price growth, wage growth, population growth)
A33: Black numbers | B33: Formulas - do not type over these
A34: Yellow shading | B34: Assumptions or judgement calls you are expected to review and change
A36: UNITS | B36: Kina millions unless stated. Growth rates are percent. Volumes as reported by DoT / commodity boards.

Sheet Dashboard
A1: PNG GDP 2025 Estimate - Dashboard
A2: Production approach, constant 2013 prices. Kina millions. All cells are formulas - change inputs on the green tabs.
A4: Real GDP growth 2025 | C4: Real GDP 2025 (K m) | E4: Non-resource growth | G4: Resource growth
A5: =E19 -> 0.050643499 | C5: =D19 -> 75827.052 | E5: =E21 -> 0.036669793 | G5: =E20 -> 0.091800931
A8: Nominal GDP 2025 (K m) | C8: Nominal GDP growth | E8: GDP deflator growth | G8: Real GDP per person
A9: =D25 -> 133255.44 | C9: =E25 -> 0.1228148 | E9: =E24 -> 0.068692474 | G9: =E27 -> 0.023573495
A12: Sector | B12: Type | C12: Real GVA 2024 | D12: Real GVA 2025 | E12: Real growth % | F12: Share of GDP 2025 | G12: Contribution to growth (pp)
A13: Oil & Gas | B13: Resource | C13: =Resource!K14 -> 12189.831 | D13: =Resource!L14 -> 13137.562 | E13: =IF(C13=0,0,D13/C13-1) -> 0.077747687 | F13: =D13/$D$19 -> 0.17325692 | G13: =(D13-C13)/$C$19*100 -> 1.3131561
A14: Mining | B14: Resource | C14: =Resource!K15 -> 6103.1062 | D14: =Resource!L15 -> 6834.6837 | E14: =IF(C14=0,0,D14/C14-1) -> 0.1198697 | F14: =D14/$D$19 -> 0.090135162 | G14: =(D14-C14)/$C$19*100 -> 1.0136582
A15: Agriculture, forestry & fishing | B15: Non-resource | C15: =AFF!G24 -> 11373.225 | D15: =AFF!H24 -> 11942.144 | E15: =IF(C15=0,0,D15/C15-1) -> 0.050022592 | F15: =D15/$D$19 -> 0.15749186 | G15: =(D15-C15)/$C$19*100 -> 0.78828097
A16: Public admin, education & health | B16: Non-resource | C16: =Public_Admin!C14 -> 8154.8087 | D16: =Public_Admin!G14 -> 8641.8727 | E16: =IF(C16=0,0,D16/C16-1) -> 0.059727206 | F16: =D16/$D$19 -> 0.1139682 | G16: =(D16-C16)/$C$19*100 -> 0.67486543
A17: Other sectors (manufacturing, services...) | B17: Non-resource | C17: =Other_Sectors!B23 -> 30889.646 | D17: =Other_Sectors!E23 -> 31706.571 | E17: =IF(C17=0,0,D17/C17-1) -> 0.026446566 | F17: =D17/$D$19 -> 0.41814327 | G17: =(D17-C17)/$C$19*100 -> 1.131914
A18: Taxes less subsidies on products | B18: Non-resource | C18: =Other_Sectors!B26 -> 3461.392 | D18: =Other_Sectors!E26 -> 3564.2192 | E18: =IF(C18=0,0,D18/C18-1) -> 0.029706898 | F18: =D18/$D$19 -> 0.047004586 | G18: =(D18-C18)/$C$19*100 -> 0.1424752
A19: GDP (constant prices) | C19: =SUM(C13:C18) -> 72172.009 | D19: =SUM(D13:D18) -> 75827.052 | E19: =D19/C19-1 -> 0.050643499 | F19: =SUM(F13:F18) -> 1 | G19: =SUM(G13:G18) -> 5.0643499
A20: of which Resource GDP | C20: =SUMIF($B$13:$B$18,"Resource",C$13:C$18) -> 18292.937 | D20: =SUMIF($B$13:$B$18,"Resource",D$13:D$18) -> 19972.245 | E20: =D20/C20-1 -> 0.091800931 | F20: =D20/$D$19 -> 0.26339209 | G20: =SUMIF($B$13:$B$18,"Resource",G$13:G$18) -> 2.3268143
A21: of which Non-resource GDP | C21: =SUMIF($B$13:$B$18,"Non-resource",C$13:C$18) -> 53879.072 | D21: =SUMIF($B$13:$B$18,"Non-resource",D$13:D$18) -> 55854.807 | E21: =D21/C21-1 -> 0.036669793 | F21: =D21/$D$19 -> 0.73660791 | G21: =SUMIF($B$13:$B$18,"Non-resource",G$13:G$18) -> 2.7375356
A23: Nominal GDP | C23: 2024 | D23: 2025 | E23: Growth %
A24: GDP deflator (IPD, 2013 = 100) | C24: 164.44021 | D24: 175.73601 | E24: =D24/C24-1 -> 0.068692474
A25: Nominal GDP = real GDP x IPD / 100 | C25: =C19*C24/100 -> 118679.8 | D25: =D19*D24/100 -> 133255.44 | E25: =D25/C25-1 -> 0.1228148
A26: Population | C26: 10185363 | D26: =C26*(1+Other_Sectors!D3) -> 10454731 | E26: =D26/C26-1 -> 0.026446566
A27: Real GDP per person (Kina) | C27: =C19*1000000/C26 -> 7085.8554 | D27: =D19*1000000/D26 -> 7252.8938 | E27: =D27/C27-1 -> 0.023573495
A29: Check: 2024 real GDP here vs forecasting model | C29: =C19 -> 72172.009 | D29: 72172.392 | E29: =IF(ABS(C29-D29)<5,"OK - matches","Check inputs") -> OK - matches
A32: Resource commodity | B32: Volume change 2025 | C32: Real GVA change (K m)
A33: Petroleum (oil) | B33: =Resource!M5 -> -0.16378425 | C33: =Resource!L5-Resource!K5 -> -172.16372
A34: LNG | B34: =Resource!M6 -> 0.068181818 | C34: =Resource!L6-Resource!K6 -> 669.71171
A35: Condensate | B35: =Resource!M7 -> 0.34202454 | C35: =Resource!L7-Resource!K7 -> 450.18315
A36: Copper | B36: =Resource!M8 -> 0.026849724 | C36: =Resource!L8-Resource!K8 -> 34.940282
A37: Gold | B37: =Resource!M9 -> 0.14863969 | C37: =Resource!L9-Resource!K9 -> 558.52619
A38: Silver | B38: =Resource!M10 -> 0.09293212 | C38: =Resource!L10-Resource!K10 -> 4.1531914
A39: Nickel | B39: =Resource!M11 -> 0.14570413 | C39: =Resource!L11-Resource!K11 -> 107.94824
A40: Cobalt | B40: =Resource!M12 -> 0.17623884 | C40: =Resource!L12-Resource!K12 -> 21.832291
A41: Household / alluvial (HH) | B41: =Resource!M13 -> 0.031 | C41: =Resource!L13-Resource!K13 -> 4.1773027
A43: How to read this
A44: - Real growth uses constant 2013 prices, so it measures change in volume of production only - not price changes.
A45: - Contribution (pp) = how many percentage points of total GDP growth come from that sector. They add up to total growth.
A46: - A big sector growing slowly can contribute more than a small sector growing fast - compare columns E and G.
A47: - Nominal GDP adds price changes (the deflator). Gold and copper prices push nominal resource GVA up far more than real.
A48: - Resource GDP is volatile (one mine or LNG shutdown swings it); non-resource GDP is what most people feel.

Sheet Resource
A1: Resource sector - 2025 estimate from Dept. of Treasury production volumes
A2: Step 1: production volumes (red, from DoT sheet). Step 2: volume growth x 2024 GVA = 2025 real GVA.
A4: Production (DoT) | B4: 2024 | C4: 2025 | D4: % change | F4: Commodity | G4: Sub-sector | H4: Volume 2024 | I4: Volume 2025 | J4: Volume growth ratio | K4: Real GVA 2024 (K m) | L4: Real GVA 2025 (K m) | M4: Real growth % | N4: Price growth ratio 2025 | O4: Nominal GVA 2024 (K m) | P4: Nominal GVA 2025 (K m) | Q4: Nominal growth %
A5: MINING | F5: Petroleum (oil) | G5: Oil & Gas | H5: =B38 -> 4.2632 | I5: =C38 -> 3.564955 | J5: =IF(H5=0,1,I5/H5) -> 0.83621575 | K5: 1051.1617 | L5: =K5*J5 -> 878.99796 | M5: =J5-1 -> -0.16378425 | N5: 0.91555314 | O5: 1494.8796 | P5: =O5*J5*N5 -> 1144.4798 | Q5: =IF(O5=0,0,P5/O5-1) -> -0.23440004
A6: Gold | F6: LNG | G6: Oil & Gas | H6: =B44 -> 440 | I6: =C44 -> 470 | J6: =IF(H6=0,1,I6/H6) -> 1.0681818 | K6: 9822.4384 | L6: =K6*J6 -> 10492.15 | M6: =J6-1 -> 0.068181818 | N6: 1.0041194 | O6: 17111.843 | P6: =O6*J6*N6 -> 18353.857 | Q6: =IF(O6=0,0,P6/O6-1) -> 0.072582137
A7: Prodn volume (tonnes) | B7: =SUM(B8:B16) -> 46.834349 | C7: =SUM(C8:C16) -> 53.795792 | D7: =IF(B7=0,"n/a",C7/B7-1) -> 0.14863969 | F7: Condensate | G7: Oil & Gas | H7: =B46 -> 5.216 | I7: =C46 -> 7 | J7: =IF(H7=0,1,I7/H7) -> 1.3420245 | K7: 1316.2305 | L7: =K7*J7 -> 1766.4137 | M7: =J7-1 -> 0.34202454 | N7: 0.91555314 | O7: 1568.7849 | P7: =O7*J7*N7 -> 1927.5579 | Q7: =IF(O7=0,0,P7/O7-1) -> 0.22869478
A8: Ok Tedi | B8: 8.2681456 | C8: 9.2797213 | D8: =IF(B8=0,"n/a",C8/B8-1) -> 0.12234615 | F8: Copper | G8: Mining | H8: =B18 -> 227.61792 | I8: =C18 -> 233.7294 | J8: =IF(H8=0,1,I8/H8) -> 1.0268497 | K8: 1301.3274 | L8: =K8*J8 -> 1336.2677 | M8: =J8-1 -> 0.026849724 | N8: 1.1644138 | O8: 2226.6943 | P8: =O8*J8*N8 -> 2662.4094 | Q8: =IF(O8=0,0,P8/O8-1) -> 0.19567799
A9: Porgera | B9: 5.8491848 | C9: 11.696682 | D9: =IF(B9=0,"n/a",C9/B9-1) -> 0.99971151 | F9: Gold | G9: Mining | H9: =B7 -> 46.834349 | I9: =C7 -> 53.795792 | J9: =IF(H9=0,1,I9/H9) -> 1.1486397 | K9: 3757.5846 | L9: =K9*J9 -> 4316.1107 | M9: =J9-1 -> 0.14863969 | N9: 1.5425082 | O9: 8723.1684 | P9: =O9*J9*N9 -> 15455.589 | Q9: =IF(O9=0,0,P9/O9-1) -> 0.77178616
A10: Misima | B10: 0 | C10: 0 | D10: =IF(B10=0,"n/a",C10/B10-1) -> n/a | F10: Silver | G10: Mining | H10: =B21 -> 44.079729 | I10: =C21 -> 48.176152 | J10: =IF(H10=0,1,I10/H10) -> 1.0929321 | K10: 44.690592 | L10: =K10*J10 -> 48.843783 | M10: =J10-1 -> 0.09293212 | N10: 1.5063251 | O10: 72.694408 | P10: =O10*J10*N10 -> 119.67761 | Q10: =IF(O10=0,0,P10/O10-1) -> 0.64631108
A11: Lihir | B11: 19.097533 | C11: 18.202595 | D11: =IF(B11=0,"n/a",C11/B11-1) -> -0.046861441 | F11: Nickel | G11: Mining | H11: =B31 -> 28669.09 | I11: =C31 -> 32846.295 | J11: =IF(H11=0,1,I11/H11) -> 1.1457041 | K11: 740.8729 | L11: =K11*J11 -> 848.82114 | M11: =J11-1 -> 0.14570413 | N11: 0.96500258 | O11: 1137.2539 | P11: =O11*J11*N11 -> 1257.3564 | Q11: =IF(O11=0,0,P11/O11-1) -> 0.10560745
A12: Tolukuma | B12: 0 | C12: 0 | D12: =IF(B12=0,"n/a",C12/B12-1) -> n/a | F12: Cobalt | G12: Mining | H12: =B34 -> 2625.19 | I12: =C34 -> 3087.8505 | J12: =IF(H12=0,1,I12/H12) -> 1.1762388 | K12: 123.87899 | L12: =K12*J12 -> 145.71128 | M12: =J12-1 -> 0.17623884 | N12: 1.4193113 | O12: 125.46986 | P12: =O12*J12*N12 -> 209.46555 | Q12: =IF(O12=0,0,P12/O12-1) -> 0.66944908
A13: Kainantu | B13: 4.3642839 | C13: 5.1160237 | D13: =IF(B13=0,"n/a",C13/B13-1) -> 0.17224816 | F13: Household / alluvial (HH) | G13: Mining | H13: n/a | I13: n/a | J13: 1.031 | K13: 134.7517 | L13: =K13*J13 -> 138.929 | M13: =J13-1 -> 0.031 | N13: 1.044141 | O13: 233.95409 | P13: =O13*J13*N13 -> 251.85376 | Q13: =IF(O13=0,0,P13/O13-1) -> 0.076509323
A14: Simberi | B14: 1.6750294 | C14: 1.5205972 | D14: =IF(B14=0,"n/a",C14/B14-1) -> -0.092196693 | F14: Oil & Gas | K14: =SUMIF($G$5:$G$13,"Oil & Gas",K$5:K$13) -> 12189.831 | L14: =SUMIF($G$5:$G$13,"Oil & Gas",L$5:L$13) -> 13137.562 | M14: =IF(K14=0,0,L14/K14-1) -> 0.077747687 | O14: =SUMIF($G$5:$G$13,"Oil & Gas",O$5:O$13) -> 20175.507 | P14: =SUMIF($G$5:$G$13,"Oil & Gas",P$5:P$13) -> 21425.894 | Q14: =IF(O14=0,0,P14/O14-1) -> 0.061975503
A15: Hidden Valley | B15: 4.5801731 | C15: 4.9801731 | D15: =IF(B15=0,"n/a",C15/B15-1) -> 0.087332944 | F15: Mining | K15: =SUMIF($G$5:$G$13,"Mining",K$5:K$13) -> 6103.1062 | L15: =SUMIF($G$5:$G$13,"Mining",L$5:L$13) -> 6834.6837 | M15: =IF(K15=0,0,L15/K15-1) -> 0.1198697 | O15: =SUMIF($G$5:$G$13,"Mining",O$5:O$13) -> 12519.235 | P15: =SUMIF($G$5:$G$13,"Mining",P$5:P$13) -> 19956.352 | Q15: =IF(O15=0,0,P15/O15-1) -> 0.59405521
A16: Small Scale Alluvial | B16: 3 | C16: 3 | D16: =IF(B16=0,"n/a",C16/B16-1) -> 0 | F16: RESOURCE SECTOR TOTAL | K16: =SUM(K5:K13) -> 18292.937 | L16: =SUM(L5:L13) -> 19972.245 | M16: =IF(K16=0,0,L16/K16-1) -> 0.091800931 | O16: =SUM(O5:O13) -> 32694.742 | P16: =SUM(P5:P13) -> 41382.246 | Q16: =IF(O16=0,0,P16/O16-1) -> 0.26571563
A17: Copper
A18: Prodn volume (000 lbs) | B18: =SUM(B19:B19) -> 227.61792 | C18: =SUM(C19:C19) -> 233.7294 | D18: =IF(B18=0,"n/a",C18/B18-1) -> 0.026849724 | F18: How to read this table:
A19: Ok Tedi | B19: 227.61792 | C19: 233.7294 | D19: =IF(B19=0,"n/a",C19/B19-1) -> 0.026849724 | F19: Volume growth ratio = 2025 volume / 2024 volume (1.149 means volume up 14.9%).
A20: Silver | F20: Real GVA 2025 = Real GVA 2024 x volume growth ratio (intermediate input share held constant, slide 5).
A21: Prodn volume (tonnes) | B21: =SUM(B22:B29) -> 44.079729 | C21: =SUM(C22:C29) -> 48.176152 | D21: =IF(B21=0,"n/a",C21/B21-1) -> 0.09293212 | F21: Nominal GVA 2025 = Nominal GVA 2024 x volume growth ratio x price growth ratio.
A22: Ok Tedi | B22: 30.894273 | C22: 31.363062 | D22: =IF(B22=0,"n/a",C22/B22-1) -> 0.01517398 | F22: Implied price deflator change = nominal growth vs real growth - e.g. gold: volume +15%, price +54%.
A23: Porgera | B23: 3.7884557 | C23: 2.9617639 | D23: =IF(B23=0,"n/a",C23/B23-1) -> -0.21821339
A24: Misima | B24: 0 | C24: 0 | D24: =IF(B24=0,"n/a",C24/B24-1) -> n/a
A25: Lihir | B25: 2.8 | C25: 2.8 | D25: =IF(B25=0,"n/a",C25/B25-1) -> 0
A26: Kainantu | B26: 1.3 | C26: 4.8025006 | D26: =IF(B26=0,"n/a",C26/B26-1) -> 2.6942312
A27: Simberi | B27: 0 | C27: 0.95182476 | D27: =IF(B27=0,"n/a",C27/B27-1) -> n/a
A28: Hidden Valley | B28: 4.297 | C28: 4.297 | D28: =IF(B28=0,"n/a",C28/B28-1) -> 0
A29: Small Scale Alluvial | B29: 1 | C29: 1 | D29: =IF(B29=0,"n/a",C29/B29-1) -> 0
A30: Nickel
A31: Prodn volume (tonnes) | B31: =SUM(B32:B32) -> 28669.09 | C31: =SUM(C32:C32) -> 32846.295 | D31: =IF(B31=0,"n/a",C31/B31-1) -> 0.14570413
A32: Ramu | B32: 28669.09 | C32: 32846.295 | D32: =IF(B32=0,"n/a",C32/B32-1) -> 0.14570413
A33: Cobalt
A34: Prodn volume (tonnes) | B34: =SUM(B35:B35) -> 2625.19 | C34: =SUM(C35:C35) -> 3087.8505 | D34: =IF(B34=0,"n/a",C34/B34-1) -> 0.17623884
A35: Ramu | B35: 2625.19 | C35: 3087.8505 | D35: =IF(B35=0,"n/a",C35/B35-1) -> 0.17623884
A36: OIL & GAS
A37: Petroleum
A38: Industry Production Volume (000 barrels) | B38: =SUM(B39:B42) -> 4.2632 | C38: =SUM(C39:C42) -> 3.564955 | D38: =IF(B38=0,"n/a",C38/B38-1) -> -0.16378425
A39: Kutubu | B39: 1.73448 | C39: 1.40379 | D39: =IF(B39=0,"n/a",C39/B39-1) -> -0.19065657
A40: Moran | B40: 1.93377 | C40: 1.639215 | D40: =IF(B40=0,"n/a",C40/B40-1) -> -0.15232163
A41: SE Manada & Agogo | B41: 0.59495 | C41: 0.52195 | D41: =IF(B41=0,"n/a",C41/B41-1) -> -0.12269939
...

Sheet AFF
A1: Agriculture, Forestry & Fishing - 2025 real GVA
A2: Formal commodities grow with industry volumes (commodity boards); informal activity grows with population.
A3: Informal sector growth (population growth, 2025) | E3: 0.026
A5: Component | B5: Group | C5: Method | D5: Volume 2024 ('000 t / m3) | E5: Volume 2025 | F5: Growth ratio | G5: Real GVA 2024 (K m) | H5: Real GVA 2025 (K m) | I5: Real growth %
A6: Cocoa | B6: Crop & animal | C6: Industry volume | D6: 41.108 | E6: 60 | F6: =IF(D6=0,1,E6/D6) -> 1.4595699 | G6: 388.67681 | H6: =G6*F6 -> 567.30098 | I6: =F6-1 -> 0.45956991
A7: Coffee | B7: Crop & animal | C7: Industry volume | D7: 49.60638 | E7: 47.36022 | F7: =IF(D7=0,1,E7/D7) -> 0.95472034 | G7: 445.2689 | H7: =G7*F7 -> 425.10728 | I7: =F7-1 -> -0.04527966
A8: Tea | B8: Crop & animal | C8: Industry volume | D8: 0.3999968 | E8: 0.4499964 | F8: =IF(D8=0,1,E8/D8) -> 1.125 | G8: 0.54390156 | H8: =G8*F8 -> 0.61188925 | I8: =F8-1 -> 0.125
A9: Copra | B9: Crop & animal | C9: Industry volume | D9: 23.018296 | E9: 27.334164 | F9: =IF(D9=0,1,E9/D9) -> 1.1874973 | G9: 10.693763 | H9: =G9*F9 -> 12.698815 | I9: =F9-1 -> 0.18749728
A10: Copra oil | B10: Crop & animal | C10: Industry volume | D10: 22.841763 | E10: 23.285384 | F10: =IF(D10=0,1,E10/D10) -> 1.0194215 | G10: 41.099421 | H10: =G10*F10 -> 41.897633 | I10: =F10-1 -> 0.0194215
A11: Palm oil | B11: Crop & animal | C11: Industry volume | D11: 617.92568 | E11: 671.93207 | F11: =IF(D11=0,1,E11/D11) -> 1.0873995 | G11: 1023.3033 | H11: =G11*F11 -> 1112.7395 | I11: =F11-1 -> 0.087399477
A12: Rubber | B12: Crop & animal | C12: Industry volume | D12: 2.7442378 | E12: 3.0749184 | F12: =IF(D12=0,1,E12/D12) -> 1.1205 | G12: 6.0998887 | H12: =G12*F12 -> 6.8349253 | I12: =F12-1 -> 0.1205
A13: Logs (formal forestry) | B13: Forestry | C13: Industry volume | D13: 2305.189 | E13: 2055.796 | F13: =IF(D13=0,1,E13/D13) -> 0.89181234 | G13: 294.84028 | H13: =G13*F13 -> 262.9422 | I13: =F13-1 -> -0.10818766
A14: Fishing (formal) | B14: Fishing | C14: Industry volume | D14: 219.92 | E14: 222.23963 | F14: =IF(D14=0,1,E14/D14) -> 1.0105476 | G14: 536.15234 | H14: =G14*F14 -> 541.80746 | I14: =F14-1 -> 0.010547599
A15: Livestock (formal) | B15: Crop & animal | C15: Model assumption | F15: 1.1218539 | G15: 1245.2906 | H15: =G15*F15 -> 1397.0341 | I15: =F15-1 -> 0.1218539
A16: Livestock (informal) | B16: Crop & animal | C16: Population | F16: =1+$E$3 -> 1.026 | G16: 540.92309 | H16: =G16*F16 -> 554.98709 | I16: =F16-1 -> 0.026
A17: Fruit & veg (informal) | B17: Crop & animal | C17: Population | F17: =1+$E$3 -> 1.026 | G17: 5378.174 | H17: =G17*F17 -> 5518.0065 | I17: =F17-1 -> 0.026
A18: Betel nut (informal) | B18: Crop & animal | C18: Population | F18: =1+$E$3 -> 1.026 | G18: 1019.0257 | H18: =G18*F18 -> 1045.5204 | I18: =F18-1 -> 0.026
A19: Forestry (informal) | B19: Forestry | C19: Population | F19: =1+$E$3 -> 1.026 | G19: 206.90577 | H19: =G19*F19 -> 212.28532 | I19: =F19-1 -> 0.026
A20: Fishing (informal) | B20: Fishing | C20: Population | F20: =1+$E$3 -> 1.026 | G20: 236.2276 | H20: =G20*F20 -> 242.36952 | I20: =F20-1 -> 0.026
A21: Crop & animal total | G21: =SUMIF($B$6:$B$20,"Crop & animal",G$6:G$20) -> 10099.099 | H21: =SUMIF($B$6:$B$20,"Crop & animal",H$6:H$20) -> 10682.739 | I21: =IF(G21=0,0,H21/G21-1) -> 0.057791263
A22: Forestry total | G22: =SUMIF($B$6:$B$20,"Forestry",G$6:G$20) -> 501.74605 | H22: =SUMIF($B$6:$B$20,"Forestry",H$6:H$20) -> 475.22752 | I22: =IF(G22=0,0,H22/G22-1) -> -0.052852493
A23: Fishing total | G23: =SUMIF($B$6:$B$20,"Fishing",G$6:G$20) -> 772.37994 | H23: =SUMIF($B$6:$B$20,"Fishing",H$6:H$20) -> 784.17698 | I23: =IF(G23=0,0,H23/G23-1) -> 0.01527362
A24: AFF TOTAL | G24: =SUM(G6:G20) -> 11373.225 | H24: =SUM(H6:H20) -> 11942.144 | I24: =IF(G24=0,0,H24/G24-1) -> 0.050022592
A26: Note: cocoa volumes jump 46% (41k -> 60k t) in the model inputs - check this with the Cocoa Board before relying on it; it alone adds ~K180m to real AFF GVA.

Sheet Public_Admin
A1: Public Administration, Education & Health - 2025 estimate
A2: Nominal growth = growth in government compensation of employees; deflator growth = government wage growth (slide 7).
A4: Govt compensation of employees 2024 (K m) | B4: 7214.8
A5: Govt compensation of employees 2025 (K m) | B5: 7859.8
A6: Nominal growth = CoE growth | B6: =B5/B4-1 -> 0.089399568
A7: Government wage growth (deflator growth) | B7: 0.028
A8: Implied real growth = (1+nominal)/(1+deflator) - 1 | B8: =(1+B6)/(1+B7)-1 -> 0.059727206
A10: Sub-sector | B10: Nominal GVA 2024 | C10: Real GVA 2024 | D10: IPD 2024 | E10: Nominal GVA 2025 | F10: IPD 2025 | G10: Real GVA 2025 | H10: Real growth %
A11: Public administration & defence | B11: 6049.1729 | C11: 4261.4492 | D11: =B11/C11*100 -> 141.95107 | E11: =B11*(1+$B$6) -> 6589.9663 | F11: =D11*(1+$B$7) -> 145.9257 | G11: =E11/F11*100 -> 4515.9736 | H11: =G11/C11-1 -> 0.059727206
A12: Education | B12: 3263.007 | C12: 2321.3374 | D12: =B12/C12*100 -> 140.56582 | E12: =B12*(1+$B$6) -> 3554.7185 | F12: =D12*(1+$B$7) -> 144.50167 | G12: =E12/F12*100 -> 2459.9844 | H12: =G12/C12-1 -> 0.059727206
A13: Health & social work | B13: 2282.0898 | C13: 1572.0222 | D13: =B13/C13*100 -> 145.16906 | E13: =B13*(1+$B$6) -> 2486.1076 | F13: =D13*(1+$B$7) -> 149.23379 | G13: =E13/F13*100 -> 1665.9147 | H13: =G13/C13-1 -> 0.059727206
A14: TOTAL | B14: =SUM(B11:B13) -> 11594.27 | C14: =SUM(C11:C13) -> 8154.8087 | D14: =B14/C14*100 -> 142.17709 | E14: =SUM(E11:E13) -> 12630.792 | F14: =E14/G14*100 -> 146.15805 | G14: =SUM(G11:G13) -> 8641.8727 | H14: =G14/C14-1 -> 0.059727206
A16: IPD (implicit price deflator) = nominal / real x 100. It measures the price level relative to the base year.

Sheet Other_Sectors
A1: Other sectors - population default or your judgement
A2: Leave the yellow column blank to use the default growth; type a rate (e.g. 4%) to override it.
A3: Default growth for sectors without data (population growth) | D3: 0.026446566
A5: Sector | B5: Real GVA 2024 (K m) | C5: Judgement growth (optional) | D5: Growth used | E5: Real GVA 2025 (K m) | F5: Reasoning recorded in the model
A6: Manufacturing | B6: 1171.4357 | D6: =IF(C6="",$D$3,C6) -> 0.026446566 | E6: =B6*(1+D6) -> 1202.4162 | F6: for 2026 choosen the average of 2022-2024 with a little bump - SWT increases merchandise imports increased, employment increased - private sector credit growth
A7: Electricity,Gas,Steam And Airconditioning Supply | B7: 618.50033 | D7: =IF(C7="",$D$3,C7) -> 0.026446566 | E7: =B7*(1+D7) -> 634.85754 | F7: Large increase in generator purchases
A8: Water Supply, Sewage, Waste Management | B8: 139.37601 | D8: =IF(C8="",$D$3,C8) -> 0.026446566 | E8: =B8*(1+D8) -> 143.06203 | F8: water increase in imports - longer term growth expected to be persistant. Sector going through lot of infrastructure detoriation. Next few years should see some growth
A9: Construction | B9: 4619.9049 | D9: =IF(C9="",$D$3,C9) -> 0.026446566 | E9: =B9*(1+D9) -> 4742.0856 | F9: Increased government spending in 2026 leading to strong growth government spending in net financial assets could increase by 19.8% (nominal). Connect PNG program in future years. Stronger private investment expected
A10: Wholesale And Retail Trade | B10: 6714.3149 | D10: =IF(C10="",$D$3,C10) -> 0.026446566 | E10: =B10*(1+D10) -> 6891.8855 | F10: for 2026 owards choosen the average of 2022-2024. Growth in imports supports this. Higher commodity prices indicative of demand. Tapered down a little for 2027. 2028 assume the fx effect stops
A11: Transport And Storage | B11: 1497.5712 | D11: =IF(C11="",$D$3,C11) -> 0.026446566 | E11: =B11*(1+D11) -> 1537.1768 | F11: average of last few years is 7.5 - going with 7 with the airniugini and png air refleeting program suggesting strong growth. Resumption of Pogera
A12: Accomodation And Food Service Activity | B12: 1203.2573 | D12: =IF(C12="",$D$3,C12) -> 0.026446566 | E12: =B12*(1+D12) -> 1235.0794 | F12: for 2026 choosen the average of 2022-2024. 2027 election plus toursim growth long term
A13: Information And Communication | B13: 2667.1339 | D13: =IF(C13="",$D$3,C13) -> 0.026446566 | E13: =B13*(1+D13) -> 2737.6704 | F13: for 2026 lowest number of last 4 years. gone for 7 as longer term growth
A14: Finance | B14: 1266.3683 | D14: =IF(C14="",$D$3,C14) -> 0.026446566 | E14: =B14*(1+D14) -> 1299.8594 | F14: increased growth in financial instiuttions in 2026. gone for average of last few years going forward
A15: Insurance | B15: 264.72042 | D15: =IF(C15="",$D$3,C15) -> 0.026446566 | E15: =B15*(1+D15) -> 271.72136
A16: Rent & Other | B16: 1480.293 | D16: =IF(C16="",$D$3,C16) -> 0.026446566 | E16: =B16*(1+D16) -> 1519.4417 | F16: slight overall growth vs last year
A17: Imputed Rent | B17: 2661.4443 | D17: =IF(C17="",$D$3,C17) -> 0.026446566 | E17: =B17*(1+D17) -> 2731.8304 | F17: slight overall growth vs last year
A18: Professional,Scientific And Technical Activities | B18: 683.59461 | D18: =IF(C18="",$D$3,C18) -> 0.026446566 | E18: =B18*(1+D18) -> 701.67334 | F18: for 2026 choosen slight bump vs recent average due to court cases etc. long term gone for the average of 2022-2024
A19: Administrative And Support Service Activities | B19: 5450.6101 | D19: =IF(C19="",$D$3,C19) -> 0.026446566 | E19: =B19*(1+D19) -> 5594.7601 | F19: slight overall growth vs last year. Increased law in order might see reduction in long term growth
A20: Arts,Entertainmentand Recreation | B20: 23.186156 | D20: =IF(C20="",$D$3,C20) -> 0.026446566 | E20: =B20*(1+D20) -> 23.79935
A21: Other Service Activities | B21: 401.91872 | D21: =IF(C21="",$D$3,C21) -> 0.026446566 | E21: =B21*(1+D21) -> 412.54809
A22: Activities Of Households As Employers | B22: 26.016286 | D22: =IF(C22="",$D$3,C22) -> 0.026446566 | E22: =B22*(1+D22) -> 26.704327 | F22: Has grown by 3.1% last few years
A23: TOTAL OTHER SECTORS | B23: =SUM(B6:B22) -> 30889.646 | D23: =E23/B23-1 -> 0.026446566 | E23: =SUM(E6:E22) -> 31706.571
A25: Taxes less subsidies on products | B25: Real 2024 (K m) | D25: Growth | E25: Real 2025 (K m) | F25: Source
A26: Taxes less subsidies (constant prices) | B26: 3461.392 | D26: =E26/B26-1 -> 0.029706898 | E26: 3564.2192 | F26: Forecasting model: GDP Constant Price GVA row 35 (nominal revenue forecast / tax IPD)
A28: Tip: the model's comments say Construction should be strong (higher govt capital spending, Connect PNG) and Transport ~7% (Air Niugini / PNG Air fleet, Porgera restart). Try entering those rates and watch the Dashboard.

Sheet History
A1: GDP history 2006-2024 (NSO actuals, from the forecasting model) + 2025 estimate
A2: Kina millions. Constant prices are 2013 prices.
A4: Year | B4: Nominal GDP (K bn) | C4: Real GDP (K bn) | D4: Real growth % | E4: Nominal growth % | F4: GDP deflator | G4: Oil & Gas | H4: Mining | I4: AFF | J4: Public admin, educ & health | K4: Other sectors | L4: Taxes less subsidies | M4: Resource share of real GDP | N4: Population | O4: Real GDP per person (K) | Q4: Resource | R4: Non-resource
A5: 2006 | B5: 25.538749 | C5: 34.355402 | F5: =B5/C5*100 -> 74.336923 | G5: 2152.1792 | H5: 5168.7549 | I5: 7536.0705 | J5: 2932.6774 | K5: 15408.375 | L5: 1157.3453 | M5: =(G5+H5)/SUM(G5:L5) -> 0.21309412 | N5: 6240325.5 | O5: =C5*1000000000/N5 -> 5505.3863 | Q5: =G5+H5 -> 7320.9341 | R5: =SUM(I5:L5) -> 27034.468
A6: 2007 | B6: 28.304313 | C6: 37.040342 | D6: =C6/C5-1 -> 0.078151893 | E6: =B6/B5-1 -> 0.10828895 | F6: =B6/C6*100 -> 76.414827 | G6: 2238.6887 | H6: 5173.1949 | I6: 7452.8412 | J6: 3617.3034 | K6: 17156.686 | L6: 1401.6282 | M6: =(G6+H6)/SUM(G6:L6) -> 0.200103 | N6: 6434817.9 | O6: =C6*1000000000/N6 -> 5756.2378 | Q6: =G6+H6 -> 7411.8836 | R6: =SUM(I6:L6) -> 29628.458
A7: 2008 | B7: 31.512438 | C7: 36.930533 | D7: =C7/C6-1 -> -0.002964577 | E7: =B7/B6-1 -> 0.113344 | F7: =B7/C7*100 -> 85.328954 | G7: 1970.166 | H7: 4989.1296 | I7: 7552.7995 | J7: 3285.4309 | K7: 17822.407 | L7: 1310.6002 | M7: =(G7+H7)/SUM(G7:L7) -> 0.18844287 | N7: 6635372.1 | O7: =C7*1000000000/N7 -> 5565.7064 | Q7: =G7+H7 -> 6959.2956 | R7: =SUM(I7:L7) -> 29971.237
A8: 2009 | B8: 32.013264 | C8: 39.441965 | D8: =C8/C7-1 -> 0.068004213 | E8: =B8/B7-1 -> 0.015892981 | F8: =B8/C8*100 -> 81.16549 | G8: 1635.6375 | H8: 6531.4098 | I8: 7991.735 | J8: 3546.0407 | K8: 18424.292 | L8: 1312.8497 | M8: =(G8+H8)/SUM(G8:L8) -> 0.20706492 | N8: 6842176.9 | O8: =C8*1000000000/N8 -> 5764.5345 | Q8: =G8+H8 -> 8167.0473 | R8: =SUM(I8:L8) -> 31274.918
A9: 2010 | B9: 38.752079 | C9: 43.436826 | D9: =C9/C8-1 -> 0.10128454 | E9: =B9/B8-1 -> 0.2105007 | F9: =B9/C9*100 -> 89.214802 | G9: 1714.9436 | H9: 6400.5523 | I9: 8216.6447 | J9: 3859.5088 | K9: 21856.202 | L9: 1388.975 | M9: =(G9+H9)/SUM(G9:L9) -> 0.18683446 | N9: 7055427.3 | O9: =C9*1000000000/N9 -> 6156.5125 | Q9: =G9+H9 -> 8115.4959 | R9: =SUM(I9:L9) -> 35321.33
A10: 2011 | B10: 42.642223 | C10: 43.917908 | D10: =C10/C9-1 -> 0.011075436 | E10: =B10/B9-1 -> 0.10038543 | F10: =B10/C10*100 -> 97.095296 | G10: 1488.9748 | H10: 5398.7034 | I10: 8286.5887 | J10: 4142.13 | K10: 23483.561 | L10: 1117.9497 | M10: =(G10+H10)/SUM(G10:L10) -> 0.15683075 | N10: 7254442 | O10: =C10*1000000000/N10 -> 6053.9333 | Q10: =G10+H10 -> 6887.6783 | R10: =SUM(I10:L10) -> 37030.23
A11: 2012 | B11: 44.371636 | C11: 45.963217 | D11: =C11/C10-1 -> 0.046571196 | E11: =B11/B10-1 -> 0.040556348 | F11: =B11/C11*100 -> 96.537271 | G11: 1463.005 | H11: 4703.1135 | I11: 8780.8193 | J11: 4282.3665 | K11: 25085.693 | L11: 1648.2207 | M11: =(G11+H11)/SUM(G11:L11) -> 0.13415332 | N11: 7446297.1 | O11: =C11*1000000000/N11 -> 6172.6274 | Q11: =G11+H11 -> 6166.1184 | R11: =SUM(I11:L11) -> 39797.099
A12: 2013 | B12: 47.721374 | C12: 47.721206 | D12: =C12/C11-1 -> 0.038247722 | E12: =B12/B11-1 -> 0.075492786 | F12: =B12/C12*100 -> 100.00035 | G12: 1515.0803 | H12: 4963.274 | I12: 9191.0489 | J12: 4699.692 | K12: 25586.311 | L12: 1765.8 | M12: =(G12+H12)/SUM(G12:L12) -> 0.1357542 | N12: 7643226.1 | O12: =C12*1000000000/N12 -> 6243.5947 | Q12: =G12+H12 -> 6478.3543 | R12: =SUM(I12:L12) -> 41242.852
A13: 2014 | B13: 57.130774 | C13: 54.184591 | D13: =C13/C12-1 -> 0.13544052 | E13: =B13/B12-1 -> 0.19717371 | F13: =B13/C13*100 -> 105.43731 | G13: 6054.8632 | H13: 5208.8111 | I13: 9502.8851 | J13: 5076.6893 | K13: 25600.157 | L13: 2741.1853 | M13: =(G13+H13)/SUM(G13:L13) -> 0.20787597 | N13: 7845363.1 | O13: =C13*1000000000/N13 -> 6906.5753 | Q13: =G13+H13 -> 11263.674 | R13: =SUM(I13:L13) -> 42920.917
A14: 2015 | B14: 60.139132 | C14: 57.748812 | D14: =C14/C13-1 -> 0.065779234 | E14: =B14/B13-1 -> 0.052657399 | F14: =B14/C14*100 -> 104.13917 | G14: 11248.566 | H14: 5337.4834 | I14: 9251.6564 | J14: 5219.0105 | K14: 24227.101 | L14: 2464.994 | M14: =(G14+H14)/SUM(G14:L14) -> 0.28721023 | N14: 8052846.1 | O14: =C14*1000000000/N14 -> 7171.2301 | Q14: =G14+H14 -> 16586.049 | R14: =SUM(I14:L14) -> 41162.762
A15: 2016 | B15: 65.038277 | C15: 60.919311 | D15: =C15/C14-1 -> 0.054901556 | E15: =B15/B14-1 -> 0.08146351 | F15: =B15/C15*100 -> 106.76135 | G15: 12859.944 | H15: 6263.9696 | I15: 9496.9212 | J15: 5505.3293 | K15: 24621.146 | L15: 2172.0011 | M15: =(G15+H15)/SUM(G15:L15) -> 0.31392202 | N15: 8265816.2 | O15: =C15*1000000000/N15 -> 7370.0298 | Q15: =G15+H15 -> 19123.914 | R15: =SUM(I15:L15) -> 41795.398
A16: 2017 | B16: 72.521646 | C16: 63.072429 | D16: =C16/C15-1 -> 0.035343765 | E16: =B16/B15-1 -> 0.115061 | F16: =B16/C16*100 -> 114.98153 | G16: 13389.912 | H16: 7277.415 | I16: 9720.4332 | J16: 5625.0689 | K16: 24464.387 | L16: 2595.2135 | M16: =(G16+H16)/SUM(G16:L16) -> 0.32767608 | N16: 8484418.6 | O16: =C16*1000000000/N16 -> 7433.9129 | Q16: =G16+H16 -> 20667.327 | R16: =SUM(I16:L16) -> 42405.103
A17: 2018 | B17: 79.404671 | C17: 62.896298 | D17: =C17/C16-1 -> -0.0027925234 | E17: =B17/B16-1 -> 0.094909934 | F17: =B17/C17*100 -> 126.24697 | G17: 11339.576 | H17: 7435.6979 | I17: 10164.749 | J17: 6020.6769 | K17: 25237.967 | L17: 2697.6311 | M17: =(G17+H17)/SUM(G17:L17) -> 0.29851159 | N17: 8708802.4 | O17: =C17*1000000000/N17 -> 7222.1524 | Q17: =G17+H17 -> 18775.274 | R17: =SUM(I17:L17) -> 44121.024
... A23: 2024 | B23: 118.68043 | C23: 72.172392 | D23: =C23/C22-1 -> 0.038883128 | E23: =B23/B22-1 -> 0.07287428 | F23: =B23/C23*100 -> 164.44021 | G23: 12189.831 | H23: 6103.1062 | I23: 11373.608 | J23: 8154.8087 | K23: 30889.646 | L23: 3461.392 | M23: =(G23+H23)/SUM(G23:L23) -> 0.2534617 | N23: 10185363 | O23: =C23*1000000000/N23 -> 7085.893 | Q23: =G23+H23 -> 18292.937 | R23: =SUM(I23:L23) -> 53879.455
A24: 2025e | B24: =Dashboard!D25/1000 -> 133.25544 | C24: =Dashboard!D19/1000 -> 75.827052 | D24: =C24/C23-1 -> 0.050637928 | E24: =B24/B23-1 -> 0.12280885 | F24: =B24/C24*100 -> 175.73601 | G24: =Dashboard!D13 -> 13137.562 | H24: =Dashboard!D14 -> 6834.6837 | I24: =Dashboard!D15 -> 11942.144 | J24: =Dashboard!D16 -> 8641.8727 | K24: =Dashboard!D17 -> 31706.571 | L24: =Dashboard!D18 -> 3564.2192 | M24: =(G24+H24)/SUM(G24:L24) -> 0.26339209 | N24: =Dashboard!D26 -> 10454731 | O24: =C24*1000000000/N24 -> 7252.8938 | Q24: =G24+H24 -> 19972.245 | R24: =SUM(I24:L24) -> 55854.807
A26: Source: 'Summary and Charts' tab of GDP_model_forecasting_2025.xlsx (NSO national accounts). 2025e row (yellow) is this workbook's estimate. Note: big jumps in 2014-2015 are PNG LNG starting production.

Sheet Model_Check
A1: Issues found in GDP_model_forecasting_2025.xlsx
A2: Why the model's 2025+ columns show DIV/0 errors or zero, and how this workbook handles each one.
A4: # | B4: Where (sheet / cells) | C4: What is wrong | D4: Effect | E4: Suggested fix (handled here as...)
A5: 1 | B5: Resource Sector, column AI (2025): mine-level volume rows e.g. 61-64, 83, 99, 120, 137-148, 165-174, 190, 206 | C5: 2025 production volumes have not been entered. | D5: Volume growth = 0/2024, so resource GVA 2025 = 0 and 2026+ = DIV/0 errors. Total GDP 2025 cannot be calculated. | E5: Paste the DoT 2025 numbers (this workbook's Resource tab uses them).
A6: 2 | B6: Resource Sector rows 190 & 206 (Nickel, Cobalt industry volumes) | C6: These are typed numbers, not SUMs of mine rows like gold/silver. | D6: Fine for 2024 but the 2025 cell is empty. | E6: Enter Ramu 2025 volume (DoT: nickel 32,846 t, cobalt 3,088 t).
A7: 3 | B7: Resource Sector row 215 (HH constant price growth ratio) 2025+ | C7: Blank - no assumption entered. | D7: HH GVA 2025 = 0. | E7: Enter 1.031 (3.1% historical growth) - used here as a yellow assumption.
A8: 4 | B8: Public Administration rows 5-6, 13-14, 21-22, 29-30, column AI onward | C8: 2025 GVA cells are empty (no formula yet). | D8: Public admin, education and health = 0 in 2025, pulling GDP down by ~K8bn. | E8: Nominal = 2024 x (1 + CoE growth); IPD = 2024 IPD x (1 + wage growth); real = nominal / IPD (slide 7).
A9: 5 | B9: AFF rows 60-64, 99-103, 112-116, 125-129, 138-142, 161-165, 174-178 (formal commodities) | C9: 2025 real GVA is computed as current-price growth / price growth, but 2025 current-price GVA is blank. | D9: DIV/0 errors for AFF 2025, which flows to GDP. | E9: Use volume growth (row 'Volumes from Industry') like coffee already does (row 77) - matches slide 5.
A10: 6 | B10: AFF rows 74, 80, 87, 100, 113 (2023 column) | C10: REF errors in 2023 constant-price GVA / growth. | D10: Historical growth rates for coffee, tea, copra and copra oil cannot be read. | E10: Re-link to the NSO 2023 numbers.
A11: 7 | B11: Summary and Charts rows 58-79 (judgement growth) | C11: Comments are written but no growth rates entered. | D11: All other sectors fall back to population growth (2.6%), ignoring the reasoning in the comments. | E11: Type the chosen rates - this workbook's Other_Sectors tab has a column for them.
A12: 8 | B12: Summary and Charts row 4 (current price GDP) 2025+ | C12: No formula beyond 2024. | D12: Nominal GDP and nominal growth % show -100% / DIV/0 errors. | E12: Link to 'GDP Current Price GVA'!AI37/1000 like row 5 does for real GDP.
A13: 9 | B13: Summary row 50 vs 'Other Assumptions' row 18 | C13: Two population growth rates: 2.645% (implied, used for sectors) vs 2.6% (used for informal AFF). | D13: Small inconsistency. | E13: Pick one source; both are kept here so the numbers match the model.
